Workbook
Name TeamList: Teams!$C$2:$C$17

Sheet README
A1: 12 ORE BOSARO 2026 — Tournament Manager
A3: Uso rapido: 1) risultati gironi in Matches e playoff in Knockout; 2) marcatori in Goals o KnockoutGoals; 3) classifiche ed Export si aggiornano automaticamente.
A5: Punti vittoria | B5: 3
A6: Punti vittoria ai rigori | B6: 2
A7: Punti sconfitta ai rigori | B7: 1
A8: Punti sconfitta | B8: 0
A9: Ordinamento classifica | B9: Punti, H2H manuale, differenza reti, gol fatti
A10: Autogol | B10: Non associato ad alcun giocatore e non conteggiato nei marcatori
A11: Fonte rose | B11: Squadre_iscritte(1).pdf
A12: Fonte calendario | B12: calendario_partite.pdf / gironi.pdf / fase_finale.pdf
A14: Modifiche v4 | B14: Export include anche marcatori aggregati per partita e tabella normalizzata match_goals.
A15: PenaltyWinner | B15: Nel foglio Matches il vincitore ai rigori è vincolato a squadra casa/trasferta della riga.
A16: GoalType | B16: Nel foglio Goals il tipo è Goal di default; cambia in Autogol solo se serve e lascia Player vuoto.
A17: Export sito: standings, top_scorers, matches, knockout e match_goals (gironi + knockout). | B17: Usa sezione matches per risultati + marcatori aggregati, oppure match_goals per dati normalizzati.
A18: ROSE: modifica numeri, giocatori e capitani soltanto nel foglio Rosters; Players e Validation sono viste automatiche.

Sheet Settings
A1: Setting | B1: Value
A2: WinPoints | B2: 3
A3: PenaltyWinPoints | B3: 2
A4: PenaltyLossPoints | B4: 1
A5: LossPoints | B5: 0
A6: MaxGoalSlotsPerMatch | B6: 12
A7: LiveReferenceDate | B7: 2026-06-28

Sheet Teams
A1: TeamID | B1: Group | C1: TeamName | D1: Players
A2: T01 | B2: A | C2: Fatine FC | D2: =COUNTIF(Players!$B$2:$B$481,A2) -> 10
A3: T02 | B3: A | C3: FC Internazionale Rovigo | D3: =COUNTIF(Players!$B$2:$B$481,A3) -> 10
A4: T03 | B4: A | C4: Moviola Utd | D4: =COUNTIF(Players!$B$2:$B$481,A4) -> 13
A5: T04 | B5: A | C5: Astolfi Impianti Elettrici | D5: =COUNTIF(Players!$B$2:$B$481,A5) -> 9
A6: T05 | B6: B | C6: Totani | D6: =COUNTIF(Players!$B$2:$B$481,A6) -> 9
A7: T06 | B7: B | C7: Vecchie Glorie Rovigo | D7: =COUNTIF(Players!$B$2:$B$481,A7) -> 11
A8: T07 | B8: B | C8: AS Bancatore | D8: =COUNTIF(Players!$B$2:$B$481,A8) -> 11
A9: T08 | B9: B | C9: Beverton | D9: =COUNTIF(Players!$B$2:$B$481,A9) -> 6
A10: T09 | B10: C | C10: Leoni di Ricky | D10: =COUNTIF(Players!$B$2:$B$481,A10) -> 9
A11: T10 | B11: C | C11: Pink 5ive | D11: =COUNTIF(Players!$B$2:$B$481,A11) -> 10
A12: T11 | B12: C | C12: Barrio Boys | D12: =COUNTIF(Players!$B$2:$B$481,A12) -> 10
A13: T12 | B13: C | C13: Cani | D13: =COUNTIF(Players!$B$2:$B$481,A13) -> 10
... A17: T16 | B17: D | C17: Piadineria la Salsiccia | D17: =COUNTIF(Players!$B$2:$B$481,A17) -> 11

Sheet Rosters
A1: Fatine FC · Girone A | D1: FC Internazionale Rovigo · Girone A | G1: Moviola Utd · Girone A | J1: Astolfi Impianti Elettrici · Girone A | M1: Totani · Girone B | P1: Vecchie Glorie Rovigo · Girone B | S1: AS Bancatore · Girone B | V1: Beverton · Girone B | Y1: Leoni di Ricky · Girone C | AB1: Pink 5ive · Girone C | AE1: Barrio Boys · Girone C | AH1: Cani · Girone C | AK1: All Blacks · Girone D | AN1: Boldò Glimt · Girone D | AQ1: Coca Juniors · Girone D | AT1: Piadineria la Salsiccia · Girone D
A2: Numero | B2: Giocatore | C2: Capitano | D2: Numero | E2: Giocatore | F2: Capitano | G2: Numero | H2: Giocatore | I2: Capitano | J2: Numero | K2: Giocatore | L2: Capitano | M2: Numero | N2: Giocatore | O2: Capitano | P2: Numero | Q2: Giocatore | R2: Capitano | S2: Numero | T2: Giocatore | U2: Capitano | V2: Numero | W2: Giocatore | X2: Capitano | Y2: Numero | Z2: Giocatore | AA2: Capitano | AB2: Numero | AC2: Giocatore | AD2: Capitano | AE2: Numero | AF2: Giocatore | AG2: Capitano | AH2: Numero | AI2: Giocatore | AJ2: Capitano | AK2: Numero | AL2: Giocatore | AM2: Capitano | AN2: Numero | AO2: Giocatore | AP2: Capitano | AQ2: Numero | AR2: Giocatore | AS2: Capitano | AT2: Numero | AU2: Giocatore | AV2: Capitano
A3: 1 | B3: PIETRO SEGATO | C3: No | E3: BOGDAN ATAMANYUK | F3: No | H3: MATTIA MERLO | I3: No | J3: 1 | K3: NICOLAS ANDRIOTTO | L3: No | M3: 5 | N3: DANIEL TARGA | O3: No | P3: 10 | Q3: DAVIDE ZAGHI | R3: Yes | S3: 1 | T3: RICCARDO BROGLIO | U3: No | V3: 4 | W3: SAMUEL MATTIELLO | X3: No | Y3: 1 | Z3: ANDREA DEGAN | AA3: No | AB3: 4 | AC3: LORENZO BOSCOLO | AD3: No | AE3: 1 | AF3: NICCOLÒ LIMAJ | AG3: No | AH3: 4 | AI3: MANUEL IMPELLICCIERI | AJ3: No | AK3: 1 | AL3: GIACOMO DE SIMONE | AM3: No | AN3: 1 | AO3: MATTIA BELLUCCO | AP3: No | AQ3: 1 | AR3: LUCA CAVALLARO | AS3: No | AT3: 1 | AU3: KEVIN CASTELLAN | AV3: No
A4: 99 | B4: GIOVANNI BALLO | C4: No | E4: IVAN DENIS SHEVERAK | F4: No | H4: MICHAEL STRENGHETTO | I4: Yes | J4: 4 | K4: GIANLUCA PAVAN | L4: No | M4: 6 | N4: RICCARDO DAVÌ | O4: No | P4: 5 | Q4: JACOPO VOLTOLINA | R4: No | S4: 2 | T4: NICOLÒ MARANGONI | U4: No | V4: 10 | W4: SAMUEL BONSU | X4: Yes | Y4: 3 | Z4: LEONARDO MAGGIO | AA4: No | AB4: 7 | AC4: ELIA SICCHIERO | AD4: No | AE4: 2 | AF4: LUCA NONNATO | AG4: No | AH4: 5 | AI4: MOURAD ECHCHARI | AJ4: No | AK4: 3 | AL4: MARTINO GRANFO | AM4: No | AN4: 2 | AO4: NICOLÒ BERTIPAGLIA | AP4: No | AQ4: 3 | AR4: KEVIN DOBROZI | AS4: No | AT4: 2 | AU4: SOUFIANE KHECHAB | AV4: No
A5: 5 | B5: DANIELE MARZOLLA | C5: No | E5: MOHAMED IAICH | F5: No | H5: LUCA BACCO | I5: No | J5: 6 | K5: NICOLA CAVALLIERI | L5: No | M5: 7 | N5: RICCARDO SANTARATO | O5: No | P5: 3 | Q5: MATTEO ZAMBERLAN | R5: No | S5: 5 | T5: MATTEO LONGO | U5: No | V5: 11 | W5: FILIPPO VENDRAMIN | X5: No | Y5: 4 | Z5: AMIN MASSAGHRI | AA5: Yes | AB5: 9 | AC5: GIOVANNI VERONESE | AD5: No | AE5: 7 | AF5: FRANCESCO BERARDI | AG5: No | AH5: 7 | AI5: OTMAN SOUATI | AJ5: No | AK5: 4 | AL5: STEFANO BRAGHIN | AM5: No | AN5: 4 | AO5: FRANCESCO CUCCATO | AP5: No | AQ5: 4 | AR5: ANDREA PAVAN | AS5: No | AT5: 3 | AU5: GABRIELE BARBIERATO | AV5: No
A6: 7 | B6: NICHOLAS MILAN | C6: No | E6: DANIIL YAKIMENKO | F6: No | H6: FILIPPO SCARANELLO | I6: No | J6: 7 | K6: ALBAN AHMATI | L6: No | M6: 9 | N6: RICCARDO STIEVANO | O6: No | P6: 20 | Q6: MATTEO DALL'ARA | R6: No | S6: 7 | T6: MATTIA ZAGO | U6: No | V6: 14 | W6: MARCO GREGGIO | X6: No | Y6: 5 | Z6: PIETRO VIOLATO | AA6: No | AB6: 10 | AC6: NICCOLO' PALTANIN | AD6: No | AE6: 8 | AF6: FRANCESCO MARANGON | AG6: No | AH6: 8 | AI6: ALEX MENEGHELLO | AJ6: No | AK6: 5 | AL6: NICOLA BRESCIANI | AM6: No | AN6: 7 | AO6: ANGELO REDI | AP6: No | AQ6: 5 | AR6: TOMMASO PAVAN | AS6: No | AT6: 4 | AU6: DAVIDE DELLA VOLPE | AV6: Yes
A7: 8 | B7: ALESSIO MILAN | C7: No | E7: AHMED ZOUZAF | F7: No | H7: EDDY MAZZETTO | I7: No | J7: 8 | K7: MARCO PREVIATO | L7: No | M7: 10 | N7: LUCA CHERUBIN | O7: Yes | P7: 8 | Q7: LEONARDO FUSCO | R7: No | S7: 8 | T7: MATTEO SAVIOLI | U7: Yes | V7: 19 | W7: CHRISTIAN ZUCCATO | X7: No | Y7: 6 | Z7: MARCO THOMPSON | AA7: No | AB7: 15 | AC7: LUCA CAVALLARO | AD7: No | AE7: 9 | AF7: GIMMY MANARI | AG7: No | AH7: 10 | AI7: ALESSIO GHIRARDELLO | AJ7: Yes | AK7: 6 | AL7: DAVIDE BEDESCHI | AM7: No | AN7: 8 | AO7: MATTEO VERZA | AP7: No | AQ7: 7 | AR7: GIAN MARCO MARANGONI | AS7: No | AT7: 5 | AU7: LUCA CEDRINO | AV7: No
A8: 10 | B8: LUCA MARINI | C8: No | E8: YOUSSEF IAICH | F8: No | H8: MATTIA BORGATO | I8: No | J8: 9 | K8: LUCA SIMEONE | L8: No | M8: 12 | N8: FILIPPO CREPALDI | O8: No | P8: 7 | Q8: DENIS TIMPANARO | R8: No | S8: 9 | T8: IGNAZIO BADALÌ | U8: No | V8: 21 | W8: MATTEO BARTOLOMEI | X8: No | Y8: 8 | Z8: GIACOMO BORTOLIERO | AA8: No | AB8: 19 | AC8: MATTEO CAMPION | AD8: No | AE8: 10 | AF8: CRISTIAN MICUCCI | AG8: Yes | AH8: 11 | AI8: ISMAIL ECHCHARI | AJ8: No | AK8: 7 | AL8: NICHOLAS MOSCHINI | AM8: No | AN8: 9 | AO8: MARCO NEODO | AP8: No | AQ8: 9 | AR8: ANDREA GREGGIO | AS8: No | AT8: 6 | AU8: ALLAL SABIL | AV8: No
A9: 11 | B9: SAMUELE DURRA | C9: No | E9: HAMZA AGRIBI | F9: Yes | H9: MARCO CASAROTTI | I9: No | J9: 10 | K9: ELIA NAGLIERI | L9: No | M9: 15 | N9: LUCA PAPARELLA | O9: No | P9: 1 | Q9: MATTEO TOSETTI | R9: No | S9: 10 | T9: GIANLUCA FREZZATI | U9: No | Y9: 10 | Z9: ANDREI BARZAGHIDEANU | AA9: No | AB9: 21 | AC9: LEONARDO BEDENDO | AD9: No | AE9: 11 | AF9: RICCARDO ALESSIO | AG9: No | AH9: 19 | AI9: LORENZO REZZAGHI | AJ9: No | AK9: 8 | AL9: DAVIDE GIRARDELLO | AM9: No | AN9: 10 | AO9: ALEX BERTIPAGLIA | AP9: Yes | AQ9: 10 | AR9: GIACOMO DOLCE | AS9: Yes | AT9: 8 | AU9: MATTIA AYRTON MARIOTTO | AV9: No
A10: 23 | B10: NICOLA MARINI | C10: Yes | E10: KHALID BENNOUNE | F10: No | H10: MATTEO NATALI | I10: No | J10: 11 | K10: FILIPPO ZANINI | L10: Yes | M10: 18 | N10: LUCA POLATO | O10: No | P10: 4 | Q10: MATTEO AMBROSINI | R10: No | S10: 11 | T10: FEDERICO MASCELLANI | U10: No | Y10: 14 | Z10: VLAD GABRIEL DUMINICA | AA10: No | AB10: 29 | AC10: LUCA BERNARDINELLO | AD10: No | AE10: 14 | AF10: EDOARDO CAVALLARI | AG10: No | AH10: 22 | AI10: TOMMASO CALZAVARINI | AJ10: No | AK10: 9 | AL10: NICOLÒ BERGANTIN | AM10: No | AN10: 14 | AO10: FABIO FERRARI | AP10: No | AQ10: 11 | AR10: CRISTIAN CAPUZZO | AS10: No | AT10: 9 | AU10: ANDREA BALDON | AV10: No
A11: 69 | B11: LUCA ROSSETTO | C11: No | E11: YASSINE SOHAYB | F11: No | H11: FRANCESCO DADDATO | I11: No | J11: 14 | K11: ALBERTO MUNERATO | L11: No | M11: 71 | N11: DANIELE SECCO | O11: No | P11: 6 | Q11: ANDREA BONIN | R11: No | S11: 13 | T11: ALBERTO OSTI | U11: No | Y11: 20 | Z11: TOMMASO ZANGIROLAMI | AA11: No | AB11: 63 | AC11: LEONARDO VERONESE | AD11: Yes | AE11: 18 | AF11: MATTEO FERRO | AG11: No | AH11: 45 | AI11: LEONARDO BULGARI | AJ11: No | AK11: 10 | AL11: FILIPPO CLEMENTE | AM11: No | AN11: 17 | AO11: NICOLA MORIN | AP11: No | AQ11: 23 | AR11: EMANUELE VERONESE | AS11: No | AT11: 10 | AU11: RAFFAELE GAROFALO | AV11: No
A12: 90 | B12: MATTEO COL | C12: No | E12: ABDESSAMAD BAGHROUCH | F12: No | H12: NICHOLAS LANZONI | I12: No | P12: 17 | Q12: DOMENICO IACOVINO | R12: No | S12: 14 | T12: LUCA ROSSI | U12: No | AB12: 95 | AC12: MATTIA COLTRO | AD12: No | AE12: 20 | AF12: ANDREA ANZOLETTI | AG12: No | AH12: 67 | AI12: RICCARDO TOGNOLO | AJ12: No | AK12: 11 | AL12: ALBERTO LORENZETTI | AM12: Yes | AN12: 21 | AO12: LUCA CECCONELLO | AP12: No | AQ12: 28 | AR12: NICOLA DOBROZI | AS12: No | AT12: 11 | AU12: ALEX BERGO | AV12: No
H13: NICOLÒ POLITI | I13: No | P13: 16 | Q13: GIACOMO PROTTI | R13: No | S13: 17 | T13: NICOLA BARONI | U13: No | AK13: 18 | AL13: MATTIA BIOLCATI | AM13: No | AT13: 7 | AU13: MATTEO BOLZANI | AV13: No
H14: MATTEO SENO | I14: No
H15: NICO PAVANI

Sheet Players
A1: PlayerID | B1: TeamID | C1: TeamName | D1: ShirtNumber | E1: PlayerName | F1: Captain | G1: DisplayName
A2: =IF(E2="","","P"&TEXT(ROW()-1,"000")) -> P001 | B2: =IF(E2="","",Teams!A2) -> T01 | C2: =IF(E2="","",Teams!C2) -> Fatine FC | D2: =IF(E2="","",Rosters!A3) -> 1 | E2: =IF(Rosters!B3="","",Rosters!B3) -> PIETRO SEGATO | F2: =IF(E2="","",Rosters!C3) -> No | G2: =IF(E2="","",IF(D2="","",D2&" - ")&E2&IF(F2="Yes"," (C)","")) -> 1 - PIETRO SEGATO
A3: =IF(E3="","","P"&TEXT(ROW()-1,"000")) -> P002 | B3: =IF(E3="","",Teams!A2) -> T01 | C3: =IF(E3="","",Teams!C2) -> Fatine FC | D3: =IF(E3="","",Rosters!A4) -> 99 | E3: =IF(Rosters!B4="","",Rosters!B4) -> GIOVANNI BALLO | F3: =IF(E3="","",Rosters!C4) -> No | G3: =IF(E3="","",IF(D3="","",D3&" - ")&E3&IF(F3="Yes"," (C)","")) -> 99 - GIOVANNI BALLO
A4: =IF(E4="","","P"&TEXT(ROW()-1,"000")) -> P003 | B4: =IF(E4="","",Teams!A2) -> T01 | C4: =IF(E4="","",Teams!C2) -> Fatine FC | D4: =IF(E4="","",Rosters!A5) -> 5 | E4: =IF(Rosters!B5="","",Rosters!B5) -> DANIELE MARZOLLA | F4: =IF(E4="","",Rosters!C5) -> No | G4: =IF(E4="","",IF(D4="","",D4&" - ")&E4&IF(F4="Yes"," (C)","")) -> 5 - DANIELE MARZOLLA
A5: =IF(E5="","","P"&TEXT(ROW()-1,"000")) -> P004 | B5: =IF(E5="","",Teams!A2) -> T01 | C5: =IF(E5="","",Teams!C2) -> Fatine FC | D5: =IF(E5="","",Rosters!A6) -> 7 | E5: =IF(Rosters!B6="","",Rosters!B6) -> NICHOLAS MILAN | F5: =IF(E5="","",Rosters!C6) -> No | G5: =IF(E5="","",IF(D5="","",D5&" - ")&E5&IF(F5="Yes"," (C)","")) -> 7 - NICHOLAS MILAN
A6: =IF(E6="","","P"&TEXT(ROW()-1,"000")) -> P005 | B6: =IF(E6="","",Teams!A2) -> T01 | C6: =IF(E6="","",Teams!C2) -> Fatine FC | D6: =IF(E6="","",Rosters!A7) -> 8 | E6: =IF(Rosters!B7="","",Rosters!B7) -> ALESSIO MILAN | F6: =IF(E6="","",Rosters!C7) -> No | G6: =IF(E6="","",IF(D6="","",D6&" - ")&E6&IF(F6="Yes"," (C)","")) -> 8 - ALESSIO MILAN
A7: =IF(E7="","","P"&TEXT(ROW()-1,"000")) -> P006 | B7: =IF(E7="","",Teams!A2) -> T01 | C7: =IF(E7="","",Teams!C2) -> Fatine FC | D7: =IF(E7="","",Rosters!A8) -> 10 | E7: =IF(Rosters!B8="","",Rosters!B8) -> LUCA MARINI | F7: =IF(E7="","",Rosters!C8) -> No | G7: =IF(E7="","",IF(D7="","",D7&" - ")&E7&IF(F7="Yes"," (C)","")) -> 10 - LUCA MARINI
A8: =IF(E8="","","P"&TEXT(ROW()-1,"000")) -> P007 | B8: =IF(E8="","",Teams!A2) -> T01 | C8: =IF(E8="","",Teams!C2) -> Fatine FC | D8: =IF(E8="","",Rosters!A9) -> 11 | E8: =IF(Rosters!B9="","",Rosters!B9) -> SAMUELE DURRA | F8: =IF(E8="","",Rosters!C9) -> No | G8: =IF(E8="","",IF(D8="","",D8&" - ")&E8&IF(F8="Yes"," (C)","")) -> 11 - SAMUELE DURRA
A9: =IF(E9="","","P"&TEXT(ROW()-1,"000")) -> P008 | B9: =IF(E9="","",Teams!A2) -> T01 | C9: =IF(E9="","",Teams!C2) -> Fatine FC | D9: =IF(E9="","",Rosters!A10) -> 23 | E9: =IF(Rosters!B10="","",Rosters!B10) -> NICOLA MARINI | F9: =IF(E9="","",Rosters!C10) -> Yes | G9: =IF(E9="","",IF(D9="","",D9&" - ")&E9&IF(F9="Yes"," (C)","")) -> 23 - NICOLA MARINI (C)
A10: =IF(E10="","","P"&TEXT(ROW()-1,"000")) -> P009 | B10: =IF(E10="","",Teams!A2) -> T01 | C10: =IF(E10="","",Teams!C2) -> Fatine FC | D10: =IF(E10="","",Rosters!A11) -> 69 | E10: =IF(Rosters!B11="","",Rosters!B11) -> LUCA ROSSETTO | F10: =IF(E10="","",Rosters!C11) -> No | G10: =IF(E10="","",IF(D10="","",D10&" - ")&E10&IF(F10="Yes"," (C)","")) -> 69 - LUCA ROSSETTO
A11: =IF(E11="","","P"&TEXT(ROW()-1,"000")) -> P010 | B11: =IF(E11="","",Teams!A2) -> T01 | C11: =IF(E11="","",Teams!C2) -> Fatine FC | D11: =IF(E11="","",Rosters!A12) -> 90 | E11: =IF(Rosters!B12="","",Rosters!B12) -> MATTEO COL | F11: =IF(E11="","",Rosters!C12) -> No | G11: =IF(E11="","",IF(D11="","",D11&" - ")&E11&IF(F11="Yes"," (C)","")) -> 90 - MATTEO COL
A12: =IF(E12="","","P"&TEXT(ROW()-1,"000")) | B12: =IF(E12="","",Teams!A2) | C12: =IF(E12="","",Teams!C2) | D12: =IF(E12="","",Rosters!A13) | E12: =IF(Rosters!B13="","",Rosters!B13) | F12: =IF(E12="","",Rosters!C13) | G12: =IF(E12="","",IF(D12="","",D12&" - ")&E12&IF(F12="Yes"," (C)",""))
A13: =IF(E13="","","P"&TEXT(ROW()-1,"000")) | B13: =IF(E13="","",Teams!A2) | C13: =IF(E13="","",Teams!C2) | D13: =IF(E13="","",Rosters!A14) | E13: =IF(Rosters!B14="","",Rosters!B14) | F13: =IF(E13="","",Rosters!C14) | G13: =IF(E13="","",IF(D13="","",D13&" - ")&E13&IF(F13="Yes"," (C)",""))
A14: =IF(E14="","","P"&TEXT(ROW()-1,"000")) | B14: =IF(E14="","",Teams!A2) | C14: =IF(E14="","",Teams!C2) | D14: =IF(E14="","",Rosters!A15) | E14: =IF(Rosters!B15="","",Rosters!B15) | F14: =IF(E14="","",Rosters!C15) | G14: =IF(E14="","",IF(D14="","",D14&" - ")&E14&IF(F14="Yes"," (C)",""))
A15: =IF(E15="","","P"&TEXT(ROW()-1,"000")) | B15: =IF(E15="","",Teams!A2) | C15: =IF(E15="","",Teams!C2) | D15: =IF(E15="","",Rosters!A16) | E15: =IF(Rosters!B16="","",Rosters!B16) | F15: =IF(E15="","",Rosters!C16) | G15: =IF(E15="","",IF(D15="","",D15&" - ")&E15&IF(F15="Yes"," (C)",""))
A16: =IF(E16="","","P"&TEXT(ROW()-1,"000")) | B16: =IF(E16="","",Teams!A2) | C16: =IF(E16="","",Teams!C2) | D16: =IF(E16="","",Rosters!A17) | E16: =IF(Rosters!B17="","",Rosters!B17) | F16: =IF(E16="","",Rosters!C17) | G16: =IF(E16="","",IF(D16="","",D16&" - ")&E16&IF(F16="Yes"," (C)",""))
A17: =IF(E17="","","P"&TEXT(ROW()-1,"000")) | B17: =IF(E17="","",Teams!A2) | C17: =IF(E17="","",Teams!C2) | D17: =IF(E17="","",Rosters!A18) | E17: =IF(Rosters!B18="","",Rosters!B18) | F17: =IF(E17="","",Rosters!C18) | G17: =IF(E17="","",IF(D17="","",D17&" - ")&E17&IF(F17="Yes"," (C)",""))
A18: =IF(E18="","","P"&TEXT(ROW()-1,"000")) | B18: =IF(E18="","",Teams!A2) | C18: =IF(E18="","",Teams!C2) | D18: =IF(E18="","",Rosters!A19) | E18: =IF(Rosters!B19="","",Rosters!B19) | F18: =IF(E18="","",Rosters!C19) | G18: =IF(E18="","",IF(D18="","",D18&" - ")&E18&IF(F18="Yes"," (C)",""))
A19: =IF(E19="","","P"&TEXT(ROW()-1,"000")) | B19: =IF(E19="","",Teams!A2) | C19: =IF(E19="","",Teams!C2) | D19: =IF(E19="","",Rosters!A20) | E19: =IF(Rosters!B20="","",Rosters!B20) | F19: =IF(E19="","",Rosters!C20) | G19: =IF(E19="","",IF(D19="","",D19&" - ")&E19&IF(F19="Yes"," (C)",""))
A20: =IF(E20="","","P"&TEXT(ROW()-1,"000")) | B20: =IF(E20="","",Teams!A2) | C20: =IF(E20="","",Teams!C2) | D20: =IF(E20="","",Rosters!A21) | E20: =IF(Rosters!B21="","",Rosters!B21) | F20: =IF(E20="","",Rosters!C21) | G20: =IF(E20="","",IF(D20="","",D20&" - ")&E20&IF(F20="Yes"," (C)",""))
A21: =IF(E21="","","P"&TEXT(ROW()-1,"000")) | B21: =IF(E21="","",Teams!A2) | C21: =IF(E21="","",Teams!C2) | D21: =IF(E21="","",Rosters!A22) | E21: =IF(Rosters!B22="","",Rosters!B22) | F21: =IF(E21="","",Rosters!C22) | G21: =IF(E21="","",IF(D21="","",D21&" - ")&E21&IF(F21="Yes"," (C)",""))
A22: =IF(E22="","","P"&TEXT(ROW()-1,"000")) | B22: =IF(E22="","",Teams!A2) | C22: =IF(E22="","",Teams!C2) | D22: =IF(E22="","",Rosters!A23) | E22: =IF(Rosters!B23="","",Rosters!B23) | F22: =IF(E22="","",Rosters!C23) | G22: =IF(E22="","",IF(D22="","",D22&" - ")&E22&IF(F22="Yes"," (C)",""))
A23: =IF(E23="","","P"&TEXT(ROW()-1,"000")) | B23: =IF(E23="","",Teams!A2) | C23: =IF(E23="","",Teams!C2) | D23: =IF(E23="","",Rosters!A24) | E23: =IF(Rosters!B24="","",Rosters!B24) | F23: =IF(E23="","",Rosters!C24) | G23: =IF(E23="","",IF(D23="","",D23&" - ")&E23&IF(F23="Yes"," (C)",""))
A24: =IF(E24="","","P"&TEXT(ROW()-1,"000")) | B24: =IF(E24="","",Teams!A2) | C24: =IF(E24="","",Teams!C2) | D24: =IF(E24="","",Rosters!A25) | E24: =IF(Rosters!B25="","",Rosters!B25) | F24: =IF(E24="","",Rosters!C25) | G24: =IF(E24="","",IF(D24="","",D24&" - ")&E24&IF(F24="Yes"," (C)",""))
A25: =IF(E25="","","P"&TEXT(ROW()-1,"000")) | B25: =IF(E25="","",Teams!A2) | C25: =IF(E25="","",Teams!C2) | D25: =IF(E25="","",Rosters!A26) | E25: =IF(Rosters!B26="","",Rosters!B26) | F25: =IF(E25="","",Rosters!C26) | G25: =IF(E25="","",IF(D25="","",D25&" - ")&E25&IF(F25="Yes"," (C)",""))
A26: =IF(E26="","","P"&TEXT(ROW()-1,"000")) | B26: =IF(E26="","",Teams!A2) | C26: =IF(E26="","",Teams!C2) | D26: =IF(E26="","",Rosters!A27) | E26: =IF(Rosters!B27="","",Rosters!B27) | F26: =IF(E26="","",Rosters!C27) | G26: =IF(E26="","",IF(D26="","",D26&" - ")&E26&IF(F26="Yes"," (C)",""))
A27: =IF(E27="","","P"&TEXT(ROW()-1,"000")) | B27: =IF(E27="","",Teams!A2) | C27: =IF(E27="","",Teams!C2) | D27: =IF(E27="","",Rosters!A28) | E27: =IF(Rosters!B28="","",Rosters!B28) | F27: =IF(E27="","",Rosters!C28) | G27: =IF(E27="","",IF(D27="","",D27&" - ")&E27&IF(F27="Yes"," (C)",""))
A28: =IF(E28="","","P"&TEXT(ROW()-1,"000")) | B28: =IF(E28="","",Teams!A2) | C28: =IF(E28="","",Teams!C2) | D28: =IF(E28="","",Rosters!A29) | E28: =IF(Rosters!B29="","",Rosters!B29) | F28: =IF(E28="","",Rosters!C29) | G28: =IF(E28="","",IF(D28="","",D28&" - ")&E28&IF(F28="Yes"," (C)",""))
A29: =IF(E29="","","P"&TEXT(ROW()-1,"000")) | B29: =IF(E29="","",Teams!A2) | C29: =IF(E29="","",Teams!C2) | D29: =IF(E29="","",Rosters!A30) | E29: =IF(Rosters!B30="","",Rosters!B30) | F29: =IF(E29="","",Rosters!C30) | G29: =IF(E29="","",IF(D29="","",D29&" - ")&E29&IF(F29="Yes"," (C)",""))
A30: =IF(E30="","","P"&TEXT(ROW()-1,"000")) | B30: =IF(E30="","",Teams!A2) | C30: =IF(E30="","",Teams!C2) | D30: =IF(E30="","",Rosters!A31) | E30: =IF(Rosters!B31="","",Rosters!B31) | F30: =IF(E30="","",Rosters!C31) | G30: =IF(E30="","",IF(D30="","",D30&" - ")&E30&IF(F30="Yes"," (C)",""))
A31: =IF(E31="","","P"&TEXT(ROW()-1,"000")) | B31: =IF(E31="","",Teams!A2) | C31: =IF(E31="","",Teams!C2) | D31: =IF(E31="","",Rosters!A32) | E31: =IF(Rosters!B32="","",Rosters!B32) | F31: =IF(E31="","",Rosters!C32) | G31: =IF(E31="","",IF(D31="","",D31&" - ")&E31&IF(F31="Yes"," (C)",""))
A32: =IF(E32="","","P"&TEXT(ROW()-1,"000")) -> P031 | B32: =IF(E32="","",Teams!A3) -> T02 | C32: =IF(E32="","",Teams!C3) -> FC Internazionale Rovigo | D32: =IF(E32="","",Rosters!D3) -> 0 | E32: =IF(Rosters!E3="","",Rosters!E3) -> BOGDAN ATAMANYUK | F32: =IF(E32="","",Rosters!F3) -> No | G32: =IF(E32="","",IF(D32="","",D32&" - ")&E32&IF(F32="Yes"," (C)","")) -> 0 - BOGDAN ATAMANYUK
A33: =IF(E33="","","P"&TEXT(ROW()-1,"000")) -> P032 | B33: =IF(E33="","",Teams!A3) -> T02 | C33: =IF(E33="","",Teams!C3) -> FC Internazionale Rovigo | D33: =IF(E33="","",Rosters!D4) -> 0 | E33: =IF(Rosters!E4="","",Rosters!E4) -> IVAN DENIS SHEVERAK | F33: =IF(E33="","",Rosters!F4) -> No | G33: =IF(E33="","",IF(D33="","",D33&" - ")&E33&IF(F33="Yes"," (C)","")) -> 0 - IVAN DENIS SHEVERAK
A34: =IF(E34="","","P"&TEXT(ROW()-1,"000")) -> P033 | B34: =IF(E34="","",Teams!A3) -> T02 | C34: =IF(E34="","",Teams!C3) -> FC Internazionale Rovigo | D34: =IF(E34="","",Rosters!D5) -> 0 | E34: =IF(Rosters!E5="","",Rosters!E5) -> MOHAMED IAICH | F34: =IF(E34="","",Rosters!F5) -> No | G34: =IF(E34="","",IF(D34="","",D34&" - ")&E34&IF(F34="Yes"," (C)","")) -> 0 - MOHAMED IAICH
A35: =IF(E35="","","P"&TEXT(ROW()-1,"000")) -> P034 | B35: =IF(E35="","",Teams!A3) -> T02 | C35: =IF(E35="","",Teams!C3) -> FC Internazionale Rovigo | D35: =IF(E35="","",Rosters!D6) -> 0 | E35: =IF(Rosters!E6="","",Rosters!E6) -> DANIIL YAKIMENKO | F35: =IF(E35="","",Rosters!F6) -> No | G35: =IF(E35="","",IF(D35="","",D35&" - ")&E35&IF(F35="Yes"," (C)","")) -> 0 - DANIIL YAKIMENKO
A36: =IF(E36="","","P"&TEXT(ROW()-1,"000")) -> P035 | B36: =IF(E36="","",Teams!A3) -> T02 | C36: =IF(E36="","",Teams!C3) -> FC Internazionale Rovigo | D36: =IF(E36="","",Rosters!D7) -> 0 | E36: =IF(Rosters!E7="","",Rosters!E7) -> AHMED ZOUZAF | F36: =IF(E36="","",Rosters!F7) -> No | G36: =IF(E36="","",IF(D36="","",D36&" - ")&E36&IF(F36="Yes"," (C)","")) -> 0 - AHMED ZOUZAF
A37: =IF(E37="","","P"&TEXT(ROW()-1,"000")) -> P036 | B37: =IF(E37="","",Teams!A3) -> T02 | C37: =IF(E37="","",Teams!C3) -> FC Internazionale Rovigo | D37: =IF(E37="","",Rosters!D8) -> 0 | E37: =IF(Rosters!E8="","",Rosters!E8) -> YOUSSEF IAICH | F37: =IF(E37="","",Rosters!F8) -> No | G37: =IF(E37="","",IF(D37="","",D37&" - ")&E37&IF(F37="Yes"," (C)","")) -> 0 - YOUSSEF IAICH
A38: =IF(E38="","","P"&TEXT(ROW()-1,"000")) -> P037 | B38: =IF(E38="","",Teams!A3) -> T02 | C38: =IF(E38="","",Teams!C3) -> FC Internazionale Rovigo | D38: =IF(E38="","",Rosters!D9) -> 0 | E38: =IF(Rosters!E9="","",Rosters!E9) -> HAMZA AGRIBI | F38: =IF(E38="","",Rosters!F9) -> Yes | G38: =IF(E38="","",IF(D38="","",D38&" - ")&E38&IF(F38="Yes"," (C)","")) -> 0 - HAMZA AGRIBI (C)
A39: =IF(E39="","","P"&TEXT(ROW()-1,"000")) -> P038 | B39: =IF(E39="","",Teams!A3) -> T02 | C39: =IF(E39="","",Teams!C3) -> FC Internazionale Rovigo | D39: =IF(E39="","",Rosters!D10) -> 0 | E39: =IF(Rosters!E10="","",Rosters!E10) -> KHALID BENNOUNE | F39: =IF(E39="","",Rosters!F10) -> No | G39: =IF(E39="","",IF(D39="","",D39&" - ")&E39&IF(F39="Yes"," (C)","")) -> 0 - KHALID BENNOUNE
A40: =IF(E40="","","P"&TEXT(ROW()-1,"000")) -> P039 | B40: =IF(E40="","",Teams!A3) -> T02 | C40: =IF(E40="","",Teams!C3) -> FC Internazionale Rovigo | D40: =IF(E40="","",Rosters!D11) -> 0 | E40: =IF(Rosters!E11="","",Rosters!E11) -> YASSINE SOHAYB | F40: =IF(E40="","",Rosters!F11) -> No | G40: =IF(E40="","",IF(D40="","",D40&" - ")&E40&IF(F40="Yes"," (C)","")) -> 0 - YASSINE SOHAYB
...

Sheet Matches
A1: MatchID | B1: Stage | C1: Group | D1: Round | E1: Field | F1: Time | G1: HomeTeam | H1: AwayTeam | I1: HomeGoals | J1: AwayGoals | K1: PenaltyWinner | L1: Status | M1: HomePoints | N1: AwayPoints | O1: Winner | P1: ScoreLabel
A2: M01 | B2: Group | C2: D | D2: 1 | E2: 1 | F2: 0.59375 | G2: All Blacks | H2: Boldò Glimt | I2: 1 | J2: 2 | L2: =IF(OR(I2="",J2=""),"Pending",IF(I2=J2,IF(K2="","Needs penalty winner","Complete"),"Complete")) -> Complete | M2: =IF(OR(I2="",J2=""),"",IF(I2>J2,Settings!$B$2,IF(I2<J2,Settings!$B$5,IF(K2=G2,Settings!$B$3,IF(K2=H2,Settings!$B$4,""))))) -> 0 | N2: =IF(OR(I2="",J2=""),"",IF(J2>I2,Settings!$B$2,IF(J2<I2,Settings!$B$5,IF(K2=H2,Settings!$B$3,IF(K2=G2,Settings!$B$4,""))))) -> 3 | O2: =IF(OR(I2="",J2=""),"",IF(I2>J2,G2,IF(J2>I2,H2,K2))) -> Boldò Glimt | P2: =IF(OR(I2="",J2=""),"",G2&" "&I2&" - "&J2&" "&H2&IF(K2<>""," (rigori: "&K2&")","")) -> All Blacks 1 - 2 Boldò Glimt
A3: M02 | B3: Group | C3: D | D3: 1 | E3: 2 | F3: 0.59375 | G3: Coca Juniors | H3: Piadineria la Salsiccia | I3: 0 | J3: 1 | L3: =IF(OR(I3="",J3=""),"Pending",IF(I3=J3,IF(K3="","Needs penalty winner","Complete"),"Complete")) -> Complete | M3: =IF(OR(I3="",J3=""),"",IF(I3>J3,Settings!$B$2,IF(I3<J3,Settings!$B$5,IF(K3=G3,Settings!$B$3,IF(K3=H3,Settings!$B$4,""))))) -> 0 | N3: =IF(OR(I3="",J3=""),"",IF(J3>I3,Settings!$B$2,IF(J3<I3,Settings!$B$5,IF(K3=H3,Settings!$B$3,IF(K3=G3,Settings!$B$4,""))))) -> 3 | O3: =IF(OR(I3="",J3=""),"",IF(I3>J3,G3,IF(J3>I3,H3,K3))) -> Piadineria la Salsiccia | P3: =IF(OR(I3="",J3=""),"",G3&" "&I3&" - "&J3&" "&H3&IF(K3<>""," (rigori: "&K3&")","")) -> Coca Juniors 0 - 1 Piadineria la Salsiccia
A4: M03 | B4: Group | C4: B | D4: 1 | E4: 3 (S) | F4: 0.59375 | G4: Totani | H4: Vecchie Glorie Rovigo | I4: 0 | J4: 10 | L4: =IF(OR(I4="",J4=""),"Pending",IF(I4=J4,IF(K4="","Needs penalty winner","Complete"),"Complete")) -> Complete | M4: =IF(OR(I4="",J4=""),"",IF(I4>J4,Settings!$B$2,IF(I4<J4,Settings!$B$5,IF(K4=G4,Settings!$B$3,IF(K4=H4,Settings!$B$4,""))))) -> 0 | N4: =IF(OR(I4="",J4=""),"",IF(J4>I4,Settings!$B$2,IF(J4<I4,Settings!$B$5,IF(K4=H4,Settings!$B$3,IF(K4=G4,Settings!$B$4,""))))) -> 3 | O4: =IF(OR(I4="",J4=""),"",IF(I4>J4,G4,IF(J4>I4,H4,K4))) -> Vecchie Glorie Rovigo | P4: =IF(OR(I4="",J4=""),"",G4&" "&I4&" - "&J4&" "&H4&IF(K4<>""," (rigori: "&K4&")","")) -> Totani 0 - 10 Vecchie Glorie Rovigo
A5: M04 | B5: Group | C5: C | D5: 1 | E5: 1 | F5: 0.61458333 | G5: Leoni di Ricky | H5: Pink 5ive | I5: 5 | J5: 0 | L5: =IF(OR(I5="",J5=""),"Pending",IF(I5=J5,IF(K5="","Needs penalty winner","Complete"),"Complete")) -> Complete | M5: =IF(OR(I5="",J5=""),"",IF(I5>J5,Settings!$B$2,IF(I5<J5,Settings!$B$5,IF(K5=G5,Settings!$B$3,IF(K5=H5,Settings!$B$4,""))))) -> 3 | N5: =IF(OR(I5="",J5=""),"",IF(J5>I5,Settings!$B$2,IF(J5<I5,Settings!$B$5,IF(K5=H5,Settings!$B$3,IF(K5=G5,Settings!$B$4,""))))) -> 0 | O5: =IF(OR(I5="",J5=""),"",IF(I5>J5,G5,IF(J5>I5,H5,K5))) -> Leoni di Ricky | P5: =IF(OR(I5="",J5=""),"",G5&" "&I5&" - "&J5&" "&H5&IF(K5<>""," (rigori: "&K5&")","")) -> Leoni di Ricky 5 - 0 Pink 5ive
A6: M05 | B6: Group | C6: C | D6: 1 | E6: 2 | F6: 0.61458333 | G6: Barrio Boys | H6: Cani | I6: 2 | J6: 0 | L6: =IF(OR(I6="",J6=""),"Pending",IF(I6=J6,IF(K6="","Needs penalty winner","Complete"),"Complete")) -> Complete | M6: =IF(OR(I6="",J6=""),"",IF(I6>J6,Settings!$B$2,IF(I6<J6,Settings!$B$5,IF(K6=G6,Settings!$B$3,IF(K6=H6,Settings!$B$4,""))))) -> 3 | N6: =IF(OR(I6="",J6=""),"",IF(J6>I6,Settings!$B$2,IF(J6<I6,Settings!$B$5,IF(K6=H6,Settings!$B$3,IF(K6=G6,Settings!$B$4,""))))) -> 0 | O6: =IF(OR(I6="",J6=""),"",IF(I6>J6,G6,IF(J6>I6,H6,K6))) -> Barrio Boys | P6: =IF(OR(I6="",J6=""),"",G6&" "&I6&" - "&J6&" "&H6&IF(K6<>""," (rigori: "&K6&")","")) -> Barrio Boys 2 - 0 Cani
A7: M06 | B7: Group | C7: B | D7: 1 | E7: 3 (S) | F7: 0.61458333 | G7: AS Bancatore | H7: Beverton | I7: 5 | J7: 0 | L7: =IF(OR(I7="",J7=""),"Pending",IF(I7=J7,IF(K7="","Needs penalty winner","Complete"),"Complete")) -> Complete | M7: =IF(OR(I7="",J7=""),"",IF(I7>J7,Settings!$B$2,IF(I7<J7,Settings!$B$5,IF(K7=G7,Settings!$B$3,IF(K7=H7,Settings!$B$4,""))))) -> 3 | N7: =IF(OR(I7="",J7=""),"",IF(J7>I7,Settings!$B$2,IF(J7<I7,Settings!$B$5,IF(K7=H7,Settings!$B$3,IF(K7=G7,Settings!$B$4,""))))) -> 0 | O7: =IF(OR(I7="",J7=""),"",IF(I7>J7,G7,IF(J7>I7,H7,K7))) -> AS Bancatore | P7: =IF(OR(I7="",J7=""),"",G7&" "&I7&" - "&J7&" "&H7&IF(K7<>""," (rigori: "&K7&")","")) -> AS Bancatore 5 - 0 Beverton
A8: M07 | B8: Group | C8: A | D8: 1 | E8: 1 | F8: 0.63541667 | G8: Fatine FC | H8: FC Internazionale Rovigo | L8: =IF(OR(I8="",J8=""),"Pending",IF(I8=J8,IF(K8="","Needs penalty winner","Complete"),"Complete")) -> Pending | M8: =IF(OR(I8="",J8=""),"",IF(I8>J8,Settings!$B$2,IF(I8<J8,Settings!$B$5,IF(K8=G8,Settings!$B$3,IF(K8=H8,Settings!$B$4,""))))) | N8: =IF(OR(I8="",J8=""),"",IF(J8>I8,Settings!$B$2,IF(J8<I8,Settings!$B$5,IF(K8=H8,Settings!$B$3,IF(K8=G8,Settings!$B$4,""))))) | O8: =IF(OR(I8="",J8=""),"",IF(I8>J8,G8,IF(J8>I8,H8,K8))) | P8: =IF(OR(I8="",J8=""),"",G8&" "&I8&" - "&J8&" "&H8&IF(K8<>""," (rigori: "&K8&")",""))
A9: M08 | B9: Group | C9: A | D9: 1 | E9: 2 | F9: 0.63541667 | G9: Moviola Utd | H9: Astolfi Impianti Elettrici | L9: =IF(OR(I9="",J9=""),"Pending",IF(I9=J9,IF(K9="","Needs penalty winner","Complete"),"Complete")) -> Pending | M9: =IF(OR(I9="",J9=""),"",IF(I9>J9,Settings!$B$2,IF(I9<J9,Settings!$B$5,IF(K9=G9,Settings!$B$3,IF(K9=H9,Settings!$B$4,""))))) | N9: =IF(OR(I9="",J9=""),"",IF(J9>I9,Settings!$B$2,IF(J9<I9,Settings!$B$5,IF(K9=H9,Settings!$B$3,IF(K9=G9,Settings!$B$4,""))))) | O9: =IF(OR(I9="",J9=""),"",IF(I9>J9,G9,IF(J9>I9,H9,K9))) | P9: =IF(OR(I9="",J9=""),"",G9&" "&I9&" - "&J9&" "&H9&IF(K9<>""," (rigori: "&K9&")",""))
A10: M09 | B10: Group | C10: D | D10: 2 | E10: 3 (S) | F10: 0.63541667 | G10: All Blacks | H10: Coca Juniors | L10: =IF(OR(I10="",J10=""),"Pending",IF(I10=J10,IF(K10="","Needs penalty winner","Complete"),"Complete")) -> Pending | M10: =IF(OR(I10="",J10=""),"",IF(I10>J10,Settings!$B$2,IF(I10<J10,Settings!$B$5,IF(K10=G10,Settings!$B$3,IF(K10=H10,Settings!$B$4,""))))) | N10: =IF(OR(I10="",J10=""),"",IF(J10>I10,Settings!$B$2,IF(J10<I10,Settings!$B$5,IF(K10=H10,Settings!$B$3,IF(K10=G10,Settings!$B$4,""))))) | O10: =IF(OR(I10="",J10=""),"",IF(I10>J10,G10,IF(J10>I10,H10,K10))) | P10: =IF(OR(I10="",J10=""),"",G10&" "&I10&" - "&J10&" "&H10&IF(K10<>""," (rigori: "&K10&")",""))
A11: M10 | B11: Group | C11: B | D11: 2 | E11: 1 | F11: 0.65625 | G11: Totani | H11: AS Bancatore | L11: =IF(OR(I11="",J11=""),"Pending",IF(I11=J11,IF(K11="","Needs penalty winner","Complete"),"Complete")) -> Pending | M11: =IF(OR(I11="",J11=""),"",IF(I11>J11,Settings!$B$2,IF(I11<J11,Settings!$B$5,IF(K11=G11,Settings!$B$3,IF(K11=H11,Settings!$B$4,""))))) | N11: =IF(OR(I11="",J11=""),"",IF(J11>I11,Settings!$B$2,IF(J11<I11,Settings!$B$5,IF(K11=H11,Settings!$B$3,IF(K11=G11,Settings!$B$4,""))))) | O11: =IF(OR(I11="",J11=""),"",IF(I11>J11,G11,IF(J11>I11,H11,K11))) | P11: =IF(OR(I11="",J11=""),"",G11&" "&I11&" - "&J11&" "&H11&IF(K11<>""," (rigori: "&K11&")",""))
A12: M11 | B12: Group | C12: B | D12: 2 | E12: 2 | F12: 0.65625 | G12: Vecchie Glorie Rovigo | H12: Beverton | L12: =IF(OR(I12="",J12=""),"Pending",IF(I12=J12,IF(K12="","Needs penalty winner","Complete"),"Complete")) -> Pending | M12: =IF(OR(I12="",J12=""),"",IF(I12>J12,Settings!$B$2,IF(I12<J12,Settings!$B$5,IF(K12=G12,Settings!$B$3,IF(K12=H12,Settings!$B$4,""))))) | N12: =IF(OR(I12="",J12=""),"",IF(J12>I12,Settings!$B$2,IF(J12<I12,Settings!$B$5,IF(K12=H12,Settings!$B$3,IF(K12=G12,Settings!$B$4,""))))) | O12: =IF(OR(I12="",J12=""),"",IF(I12>J12,G12,IF(J12>I12,H12,K12))) | P12: =IF(OR(I12="",J12=""),"",G12&" "&I12&" - "&J12&" "&H12&IF(K12<>""," (rigori: "&K12&")",""))
A13: M12 | B13: Group | C13: D | D13: 2 | E13: 3 (S) | F13: 0.65625 | G13: Boldò Glimt | H13: Piadineria la Salsiccia | L13: =IF(OR(I13="",J13=""),"Pending",IF(I13=J13,IF(K13="","Needs penalty winner","Complete"),"Complete")) -> Pending | M13: =IF(OR(I13="",J13=""),"",IF(I13>J13,Settings!$B$2,IF(I13<J13,Settings!$B$5,IF(K13=G13,Settings!$B$3,IF(K13=H13,Settings!$B$4,""))))) | N13: =IF(OR(I13="",J13=""),"",IF(J13>I13,Settings!$B$2,IF(J13<I13,Settings!$B$5,IF(K13=H13,Settings!$B$3,IF(K13=G13,Settings!$B$4,""))))) | O13: =IF(OR(I13="",J13=""),"",IF(I13>J13,G13,IF(J13>I13,H13,K13))) | P13: =IF(OR(I13="",J13=""),"",G13&" "&I13&" - "&J13&" "&H13&IF(K13<>""," (rigori: "&K13&")",""))
A14: M13 | B14: Group | C14: C | D14: 2 | E14: 1 | F14: 0.6875 | G14: Leoni di Ricky | H14: Barrio Boys | L14: =IF(OR(I14="",J14=""),"Pending",IF(I14=J14,IF(K14="","Needs penalty winner","Complete"),"Complete")) -> Pending | M14: =IF(OR(I14="",J14=""),"",IF(I14>J14,Settings!$B$2,IF(I14<J14,Settings!$B$5,IF(K14=G14,Settings!$B$3,IF(K14=H14,Settings!$B$4,""))))) | N14: =IF(OR(I14="",J14=""),"",IF(J14>I14,Settings!$B$2,IF(J14<I14,Settings!$B$5,IF(K14=H14,Settings!$B$3,IF(K14=G14,Settings!$B$4,""))))) | O14: =IF(OR(I14="",J14=""),"",IF(I14>J14,G14,IF(J14>I14,H14,K14))) | P14: =IF(OR(I14="",J14=""),"",G14&" "&I14&" - "&J14&" "&H14&IF(K14<>""," (rigori: "&K14&")",""))
A15: M14 | B15: Group | C15: C | D15: 2 | E15: 2 | F15: 0.6875 | G15: Pink 5ive | H15: Cani | L15: =IF(OR(I15="",J15=""),"Pending",IF(I15=J15,IF(K15="","Needs penalty winner","Complete"),"Complete")) -> Pending | M15: =IF(OR(I15="",J15=""),"",IF(I15>J15,Settings!$B$2,IF(I15<J15,Settings!$B$5,IF(K15=G15,Settings!$B$3,IF(K15=H15,Settings!$B$4,""))))) | N15: =IF(OR(I15="",J15=""),"",IF(J15>I15,Settings!$B$2,IF(J15<I15,Settings!$B$5,IF(K15=H15,Settings!$B$3,IF(K15=G15,Settings!$B$4,""))))) | O15: =IF(OR(I15="",J15=""),"",IF(I15>J15,G15,IF(J15>I15,H15,K15))) | P15: =IF(OR(I15="",J15=""),"",G15&" "&I15&" - "&J15&" "&H15&IF(K15<>""," (rigori: "&K15&")",""))
A16: M15 | B16: Group | C16: A | D16: 2 | E16: 3 (S) | F16: 0.6875 | G16: Fatine FC | H16: Moviola Utd | L16: =IF(OR(I16="",J16=""),"Pending",IF(I16=J16,IF(K16="","Needs penalty winner","Complete"),"Complete")) -> Pending | M16: =IF(OR(I16="",J16=""),"",IF(I16>J16,Settings!$B$2,IF(I16<J16,Settings!$B$5,IF(K16=G16,Settings!$B$3,IF(K16=H16,Settings!$B$4,""))))) | N16: =IF(OR(I16="",J16=""),"",IF(J16>I16,Settings!$B$2,IF(J16<I16,Settings!$B$5,IF(K16=H16,Settings!$B$3,IF(K16=G16,Settings!$B$4,""))))) | O16: =IF(OR(I16="",J16=""),"",IF(I16>J16,G16,IF(J16>I16,H16,K16))) | P16: =IF(OR(I16="",J16=""),"",G16&" "&I16&" - "&J16&" "&H16&IF(K16<>""," (rigori: "&K16&")",""))
A17: M16 | B17: Group | C17: D | D17: 3 | E17: 1 | F17: 0.70833333 | G17: All Blacks | H17: Piadineria la Salsiccia | L17: =IF(OR(I17="",J17=""),"Pending",IF(I17=J17,IF(K17="","Needs penalty winner","Complete"),"Complete")) -> Pending | M17: =IF(OR(I17="",J17=""),"",IF(I17>J17,Settings!$B$2,IF(I17<J17,Settings!$B$5,IF(K17=G17,Settings!$B$3,IF(K17=H17,Settings!$B$4,""))))) | N17: =IF(OR(I17="",J17=""),"",IF(J17>I17,Settings!$B$2,IF(J17<I17,Settings!$B$5,IF(K17=H17,Settings!$B$3,IF(K17=G17,Settings!$B$4,""))))) | O17: =IF(OR(I17="",J17=""),"",IF(I17>J17,G17,IF(J17>I17,H17,K17))) | P17: =IF(OR(I17="",J17=""),"",G17&" "&I17&" - "&J17&" "&H17&IF(K17<>""," (rigori: "&K17&")",""))
A18: M17 | B18: Group | C18: D | D18: 3 | E18: 2 | F18: 0.70833333 | G18: Boldò Glimt | H18: Coca Juniors | L18: =IF(OR(I18="",J18=""),"Pending",IF(I18=J18,IF(K18="","Needs penalty winner","Complete"),"Complete")) -> Pending | M18: =IF(OR(I18="",J18=""),"",IF(I18>J18,Settings!$B$2,IF(I18<J18,Settings!$B$5,IF(K18=G18,Settings!$B$3,IF(K18=H18,Settings!$B$4,""))))) | N18: =IF(OR(I18="",J18=""),"",IF(J18>I18,Settings!$B$2,IF(J18<I18,Settings!$B$5,IF(K18=H18,Settings!$B$3,IF(K18=G18,Settings!$B$4,""))))) | O18: =IF(OR(I18="",J18=""),"",IF(I18>J18,G18,IF(J18>I18,H18,K18))) | P18: =IF(OR(I18="",J18=""),"",G18&" "&I18&" - "&J18&" "&H18&IF(K18<>""," (rigori: "&K18&")",""))
A19: M18 | B19: Group | C19: A | D19: 2 | E19: 3 (S) | F19: 0.70833333 | G19: FC Internazionale Rovigo | H19: Astolfi Impianti Elettrici | L19: =IF(OR(I19="",J19=""),"Pending",IF(I19=J19,IF(K19="","Needs penalty winner","Complete"),"Complete")) -> Pending | M19: =IF(OR(I19="",J19=""),"",IF(I19>J19,Settings!$B$2,IF(I19<J19,Settings!$B$5,IF(K19=G19,Settings!$B$3,IF(K19=H19,Settings!$B$4,""))))) | N19: =IF(OR(I19="",J19=""),"",IF(J19>I19,Settings!$B$2,IF(J19<I19,Settings!$B$5,IF(K19=H19,Settings!$B$3,IF(K19=G19,Settings!$B$4,""))))) | O19: =IF(OR(I19="",J19=""),"",IF(I19>J19,G19,IF(J19>I19,H19,K19))) | P19: =IF(OR(I19="",J19=""),"",G19&" "&I19&" - "&J19&" "&H19&IF(K19<>""," (rigori: "&K19&")",""))
... A25: M24 | B25: Group | C25: C | D25: 3 | E25: 3 (S) | F25: 0.75 | G25: Pink 5ive | H25: Barrio Boys | L25: =IF(OR(I25="",J25=""),"Pending",IF(I25=J25,IF(K25="","Needs penalty winner","Complete"),"Complete")) -> Pending | M25: =IF(OR(I25="",J25=""),"",IF(I25>J25,Settings!$B$2,IF(I25<J25,Settings!$B$5,IF(K25=G25,Settings!$B$3,IF(K25=H25,Settings!$B$4,""))))) | N25: =IF(OR(I25="",J25=""),"",IF(J25>I25,Settings!$B$2,IF(J25<I25,Settings!$B$5,IF(K25=H25,Settings!$B$3,IF(K25=G25,Settings!$B$4,""))))) | O25: =IF(OR(I25="",J25=""),"",IF(I25>J25,G25,IF(J25>I25,H25,K25))) | P25: =IF(OR(I25="",J25=""),"",G25&" "&I25&" - "&J25&" "&H25&IF(K25<>""," (rigori: "&K25&")",""))

Sheet Goals
A1: MatchID | B1: GoalForTeam | C1: GoalSlot | D1: GoalType | E1: Player | F1: ScorerTeam | G1: Status | H1: PlayerListRange | I1: MatchRow | J1: Slot | K1: Note
A2: =IF(OR(INDEX(Matches!$I$2:$I$25,I2-1)="",INDEX(Matches!$J$2:$J$25,I2-1)=""),"",IF(J2<=INDEX(Matches!$I$2:$I$25,I2-1)+INDEX(Matches!$J$2:$J$25,I2-1),INDEX(Matches!$A$2:$A$25,I2-1),"")) -> M01 | B2: =IF(A2="","",IF(J2<=INDEX(Matches!$I$2:$I$25,I2-1),INDEX(Matches!$G$2:$G$25,I2-1),INDEX(Matches!$H$2:$H$25,I2-1))) -> All Blacks | C2: =IF(A2="","",COUNTIFS($A$2:A2,A2,$B$2:B2,B2)) -> 1 | D2: =IF(A2="","","Goal") -> Goal | E2: 5 - NICOLA BRESCIANI | F2: =IF(A2="","",IF(D2="Autogol","",IF(D2="Goal",B2,""))) -> All Blacks | G2: =IF(A2="","",IF(D2="","Manca tipo",IF(D2="Goal",IF(E2="","Manca giocatore","OK"),IF(D2="Autogol",IF(E2<>"","Autogol: svuota Player","OK"),"Tipo non valido")))) -> OK | H2: =IF(F2="","",VLOOKUP(F2,Validation!$A$2:$B$17,2,FALSE)) -> Validation!$O$2:$O$31 | I2: =INT((ROW()-2)/Settings!$B$6)+2 -> 2 | J2: =MOD(ROW()-2,Settings!$B$6)+1 -> 1 | K2: Autogol: lasciare Player vuoto; non viene conteggiato nella classifica marcatori.
A3: =IF(OR(INDEX(Matches!$I$2:$I$25,I3-1)="",INDEX(Matches!$J$2:$J$25,I3-1)=""),"",IF(J3<=INDEX(Matches!$I$2:$I$25,I3-1)+INDEX(Matches!$J$2:$J$25,I3-1),INDEX(Matches!$A$2:$A$25,I3-1),"")) -> M01 | B3: =IF(A3="","",IF(J3<=INDEX(Matches!$I$2:$I$25,I3-1),INDEX(Matches!$G$2:$G$25,I3-1),INDEX(Matches!$H$2:$H$25,I3-1))) -> Boldò Glimt | C3: =IF(A3="","",COUNTIFS($A$2:A3,A3,$B$2:B3,B3)) -> 1 | D3: =IF(A3="","","Goal") -> Goal | E3: 21 - LUCA CECCONELLO | F3: =IF(A3="","",IF(D3="Autogol","",IF(D3="Goal",B3,""))) -> Boldò Glimt | G3: =IF(A3="","",IF(D3="","Manca tipo",IF(D3="Goal",IF(E3="","Manca giocatore","OK"),IF(D3="Autogol",IF(E3<>"","Autogol: svuota Player","OK"),"Tipo non valido")))) -> OK | H3: =IF(F3="","",VLOOKUP(F3,Validation!$A$2:$B$17,2,FALSE)) -> Validation!$P$2:$P$31 | I3: =INT((ROW()-2)/Settings!$B$6)+2 -> 2 | J3: =MOD(ROW()-2,Settings!$B$6)+1 -> 2
A4: =IF(OR(INDEX(Matches!$I$2:$I$25,I4-1)="",INDEX(Matches!$J$2:$J$25,I4-1)=""),"",IF(J4<=INDEX(Matches!$I$2:$I$25,I4-1)+INDEX(Matches!$J$2:$J$25,I4-1),INDEX(Matches!$A$2:$A$25,I4-1),"")) -> M01 | B4: =IF(A4="","",IF(J4<=INDEX(Matches!$I$2:$I$25,I4-1),INDEX(Matches!$G$2:$G$25,I4-1),INDEX(Matches!$H$2:$H$25,I4-1))) -> Boldò Glimt | C4: =IF(A4="","",COUNTIFS($A$2:A4,A4,$B$2:B4,B4)) -> 2 | D4: =IF(A4="","","Goal") -> Goal | E4: 21 - LUCA CECCONELLO | F4: =IF(A4="","",IF(D4="Autogol","",IF(D4="Goal",B4,""))) -> Boldò Glimt | G4: =IF(A4="","",IF(D4="","Manca tipo",IF(D4="Goal",IF(E4="","Manca giocatore","OK"),IF(D4="Autogol",IF(E4<>"","Autogol: svuota Player","OK"),"Tipo non valido")))) -> OK | H4: =IF(F4="","",VLOOKUP(F4,Validation!$A$2:$B$17,2,FALSE)) -> Validation!$P$2:$P$31 | I4: =INT((ROW()-2)/Settings!$B$6)+2 -> 2 | J4: =MOD(ROW()-2,Settings!$B$6)+1 -> 3
A5: =IF(OR(INDEX(Matches!$I$2:$I$25,I5-1)="",INDEX(Matches!$J$2:$J$25,I5-1)=""),"",IF(J5<=INDEX(Matches!$I$2:$I$25,I5-1)+INDEX(Matches!$J$2:$J$25,I5-1),INDEX(Matches!$A$2:$A$25,I5-1),"")) | B5: =IF(A5="","",IF(J5<=INDEX(Matches!$I$2:$I$25,I5-1),INDEX(Matches!$G$2:$G$25,I5-1),INDEX(Matches!$H$2:$H$25,I5-1))) | C5: =IF(A5="","",COUNTIFS($A$2:A5,A5,$B$2:B5,B5)) | D5: =IF(A5="","","Goal") | F5: =IF(A5="","",IF(D5="Autogol","",IF(D5="Goal",B5,""))) | G5: =IF(A5="","",IF(D5="","Manca tipo",IF(D5="Goal",IF(E5="","Manca giocatore","OK"),IF(D5="Autogol",IF(E5<>"","Autogol: svuota Player","OK"),"Tipo non valido")))) | H5: =IF(F5="","",VLOOKUP(F5,Validation!$A$2:$B$17,2,FALSE)) | I5: =INT((ROW()-2)/Settings!$B$6)+2 -> 2 | J5: =MOD(ROW()-2,Settings!$B$6)+1 -> 4
A6: =IF(OR(INDEX(Matches!$I$2:$I$25,I6-1)="",INDEX(Matches!$J$2:$J$25,I6-1)=""),"",IF(J6<=INDEX(Matches!$I$2:$I$25,I6-1)+INDEX(Matches!$J$2:$J$25,I6-1),INDEX(Matches!$A$2:$A$25,I6-1),"")) | B6: =IF(A6="","",IF(J6<=INDEX(Matches!$I$2:$I$25,I6-1),INDEX(Matches!$G$2:$G$25,I6-1),INDEX(Matches!$H$2:$H$25,I6-1))) | C6: =IF(A6="","",COUNTIFS($A$2:A6,A6,$B$2:B6,B6)) | D6: =IF(A6="","","Goal") | F6: =IF(A6="","",IF(D6="Autogol","",IF(D6="Goal",B6,""))) | G6: =IF(A6="","",IF(D6="","Manca tipo",IF(D6="Goal",IF(E6="","Manca giocatore","OK"),IF(D6="Autogol",IF(E6<>"","Autogol: svuota Player","OK"),"Tipo non valido")))) | H6: =IF(F6="","",VLOOKUP(F6,Validation!$A$2:$B$17,2,FALSE)) | I6: =INT((ROW()-2)/Settings!$B$6)+2 -> 2 | J6: =MOD(ROW()-2,Settings!$B$6)+1 -> 5
A7: =IF(OR(INDEX(Matches!$I$2:$I$25,I7-1)="",INDEX(Matches!$J$2:$J$25,I7-1)=""),"",IF(J7<=INDEX(Matches!$I$2:$I$25,I7-1)+INDEX(Matches!$J$2:$J$25,I7-1),INDEX(Matches!$A$2:$A$25,I7-1),"")) | B7: =IF(A7="","",IF(J7<=INDEX(Matches!$I$2:$I$25,I7-1),INDEX(Matches!$G$2:$G$25,I7-1),INDEX(Matches!$H$2:$H$25,I7-1))) | C7: =IF(A7="","",COUNTIFS($A$2:A7,A7,$B$2:B7,B7)) | D7: =IF(A7="","","Goal") | F7: =IF(A7="","",IF(D7="Autogol","",IF(D7="Goal",B7,""))) | G7: =IF(A7="","",IF(D7="","Manca tipo",IF(D7="Goal",IF(E7="","Manca giocatore","OK"),IF(D7="Autogol",IF(E7<>"","Autogol: svuota Player","OK"),"Tipo non valido")))) | H7: =IF(F7="","",VLOOKUP(F7,Validation!$A$2:$B$17,2,FALSE)) | I7: =INT((ROW()-2)/Settings!$B$6)+2 -> 2 | J7: =MOD(ROW()-2,Settings!$B$6)+1 -> 6
A8: =IF(OR(INDEX(Matches!$I$2:$I$25,I8-1)="",INDEX(Matches!$J$2:$J$25,I8-1)=""),"",IF(J8<=INDEX(Matches!$I$2:$I$25,I8-1)+INDEX(Matches!$J$2:$J$25,I8-1),INDEX(Matches!$A$2:$A$25,I8-1),"")) | B8: =IF(A8="","",IF(J8<=INDEX(Matches!$I$2:$I$25,I8-1),INDEX(Matches!$G$2:$G$25,I8-1),INDEX(Matches!$H$2:$H$25,I8-1))) | C8: =IF(A8="","",COUNTIFS($A$2:A8,A8,$B$2:B8,B8)) | D8: =IF(A8="","","Goal") | F8: =IF(A8="","",IF(D8="Autogol","",IF(D8="Goal",B8,""))) | G8: =IF(A8="","",IF(D8="","Manca tipo",IF(D8="Goal",IF(E8="","Manca giocatore","OK"),IF(D8="Autogol",IF(E8<>"","Autogol: svuota Player","OK"),"Tipo non valido")))) | H8: =IF(F8="","",VLOOKUP(F8,Validation!$A$2:$B$17,2,FALSE)) | I8: =INT((ROW()-2)/Settings!$B$6)+2 -> 2 | J8: =MOD(ROW()-2,Settings!$B$6)+1 -> 7
A9: =IF(OR(INDEX(Matches!$I$2:$I$25,I9-1)="",INDEX(Matches!$J$2:$J$25,I9-1)=""),"",IF(J9<=INDEX(Matches!$I$2:$I$25,I9-1)+INDEX(Matches!$J$2:$J$25,I9-1),INDEX(Matches!$A$2:$A$25,I9-1),"")) | B9: =IF(A9="","",IF(J9<=INDEX(Matches!$I$2:$I$25,I9-1),INDEX(Matches!$G$2:$G$25,I9-1),INDEX(Matches!$H$2:$H$25,I9-1))) | C9: =IF(A9="","",COUNTIFS($A$2:A9,A9,$B$2:B9,B9)) | D9: =IF(A9="","","Goal") | F9: =IF(A9="","",IF(D9="Autogol","",IF(D9="Goal",B9,""))) | G9: =IF(A9="","",IF(D9="","Manca tipo",IF(D9="Goal",IF(E9="","Manca giocatore","OK"),IF(D9="Autogol",IF(E9<>"","Autogol: svuota Player","OK"),"Tipo non valido")))) | H9: =IF(F9="","",VLOOKUP(F9,Validation!$A$2:$B$17,2,FALSE)) | I9: =INT((ROW()-2)/Settings!$B$6)+2 -> 2 | J9: =MOD(ROW()-2,Settings!$B$6)+1 -> 8
A10: =IF(OR(INDEX(Matches!$I$2:$I$25,I10-1)="",INDEX(Matches!$J$2:$J$25,I10-1)=""),"",IF(J10<=INDEX(Matches!$I$2:$I$25,I10-1)+INDEX(Matches!$J$2:$J$25,I10-1),INDEX(Matches!$A$2:$A$25,I10-1),"")) | B10: =IF(A10="","",IF(J10<=INDEX(Matches!$I$2:$I$25,I10-1),INDEX(Matches!$G$2:$G$25,I10-1),INDEX(Matches!$H$2:$H$25,I10-1))) | C10: =IF(A10="","",COUNTIFS($A$2:A10,A10,$B$2:B10,B10)) | D10: =IF(A10="","","Goal") | F10: =IF(A10="","",IF(D10="Autogol","",IF(D10="Goal",B10,""))) | G10: =IF(A10="","",IF(D10="","Manca tipo",IF(D10="Goal",IF(E10="","Manca giocatore","OK"),IF(D10="Autogol",IF(E10<>"","Autogol: svuota Player","OK"),"Tipo non valido")))) | H10: =IF(F10="","",VLOOKUP(F10,Validation!$A$2:$B$17,2,FALSE)) | I10: =INT((ROW()-2)/Settings!$B$6)+2 -> 2 | J10: =MOD(ROW()-2,Settings!$B$6)+1 -> 9
A11: =IF(OR(INDEX(Matches!$I$2:$I$25,I11-1)="",INDEX(Matches!$J$2:$J$25,I11-1)=""),"",IF(J11<=INDEX(Matches!$I$2:$I$25,I11-1)+INDEX(Matches!$J$2:$J$25,I11-1),INDEX(Matches!$A$2:$A$25,I11-1),"")) | B11: =IF(A11="","",IF(J11<=INDEX(Matches!$I$2:$I$25,I11-1),INDEX(Matches!$G$2:$G$25,I11-1),INDEX(Matches!$H$2:$H$25,I11-1))) | C11: =IF(A11="","",COUNTIFS($A$2:A11,A11,$B$2:B11,B11)) | D11: =IF(A11="","","Goal") | F11: =IF(A11="","",IF(D11="Autogol","",IF(D11="Goal",B11,""))) | G11: =IF(A11="","",IF(D11="","Manca tipo",IF(D11="Goal",IF(E11="","Manca giocatore","OK"),IF(D11="Autogol",IF(E11<>"","Autogol: svuota Player","OK"),"Tipo non valido")))) | H11: =IF(F11="","",VLOOKUP(F11,Validation!$A$2:$B$17,2,FALSE)) | I11: =INT((ROW()-2)/Settings!$B$6)+2 -> 2 | J11: =MOD(ROW()-2,Settings!$B$6)+1 -> 10
A12: =IF(OR(INDEX(Matches!$I$2:$I$25,I12-1)="",INDEX(Matches!$J$2:$J$25,I12-1)=""),"",IF(J12<=INDEX(Matches!$I$2:$I$25,I12-1)+INDEX(Matches!$J$2:$J$25,I12-1),INDEX(Matches!$A$2:$A$25,I12-1),"")) | B12: =IF(A12="","",IF(J12<=INDEX(Matches!$I$2:$I$25,I12-1),INDEX(Matches!$G$2:$G$25,I12-1),INDEX(Matches!$H$2:$H$25,I12-1))) | C12: =IF(A12="","",COUNTIFS($A$2:A12,A12,$B$2:B12,B12)) | D12: =IF(A12="","","Goal") | F12: =IF(A12="","",IF(D12="Autogol","",IF(D12="Goal",B12,""))) | G12: =IF(A12="","",IF(D12="","Manca tipo",IF(D12="Goal",IF(E12="","Manca giocatore","OK"),IF(D12="Autogol",IF(E12<>"","Autogol: svuota Player","OK"),"Tipo non valido")))) | H12: =IF(F12="","",VLOOKUP(F12,Validation!$A$2:$B$17,2,FALSE)) | I12: =INT((ROW()-2)/Settings!$B$6)+2 -> 2 | J12: =MOD(ROW()-2,Settings!$B$6)+1 -> 11
A13: =IF(OR(INDEX(Matches!$I$2:$I$25,I13-1)="",INDEX(Matches!$J$2:$J$25,I13-1)=""),"",IF(J13<=INDEX(Matches!$I$2:$I$25,I13-1)+INDEX(Matches!$J$2:$J$25,I13-1),INDEX(Matches!$A$2:$A$25,I13-1),"")) | B13: =IF(A13="","",IF(J13<=INDEX(Matches!$I$2:$I$25,I13-1),INDEX(Matches!$G$2:$G$25,I13-1),INDEX(Matches!$H$2:$H$25,I13-1))) | C13: =IF(A13="","",COUNTIFS($A$2:A13,A13,$B$2:B13,B13)) | D13: =IF(A13="","","Goal") | F13: =IF(A13="","",IF(D13="Autogol","",IF(D13="Goal",B13,""))) | G13: =IF(A13="","",IF(D13="","Manca tipo",IF(D13="Goal",IF(E13="","Manca giocatore","OK"),IF(D13="Autogol",IF(E13<>"","Autogol: svuota Player","OK"),"Tipo non valido")))) | H13: =IF(F13="","",VLOOKUP(F13,Validation!$A$2:$B$17,2,FALSE)) | I13: =INT((ROW()-2)/Settings!$B$6)+2 -> 2 | J13: =MOD(ROW()-2,Settings!$B$6)+1 -> 12
A14: =IF(OR(INDEX(Matches!$I$2:$I$25,I14-1)="",INDEX(Matches!$J$2:$J$25,I14-1)=""),"",IF(J14<=INDEX(Matches!$I$2:$I$25,I14-1)+INDEX(Matches!$J$2:$J$25,I14-1),INDEX(Matches!$A$2:$A$25,I14-1),"")) -> M02 | B14: =IF(A14="","",IF(J14<=INDEX(Matches!$I$2:$I$25,I14-1),INDEX(Matches!$G$2:$G$25,I14-1),INDEX(Matches!$H$2:$H$25,I14-1))) -> Piadineria la Salsiccia | C14: =IF(A14="","",COUNTIFS($A$2:A14,A14,$B$2:B14,B14)) -> 1 | D14: Goal | E14: 8 - MATTIA AYRTON MARIOTTO | F14: =IF(A14="","",IF(D14="Autogol","",IF(D14="Goal",B14,""))) -> Piadineria la Salsiccia | G14: =IF(A14="","",IF(D14="","Manca tipo",IF(D14="Goal",IF(E14="","Manca giocatore","OK"),IF(D14="Autogol",IF(E14<>"","Autogol: svuota Player","OK"),"Tipo non valido")))) -> OK | H14: =IF(F14="","",VLOOKUP(F14,Validation!$A$2:$B$17,2,FALSE)) -> Validation!$R$2:$R$31 | I14: =INT((ROW()-2)/Settings!$B$6)+2 -> 3 | J14: =MOD(ROW()-2,Settings!$B$6)+1 -> 1
A15: =IF(OR(INDEX(Matches!$I$2:$I$25,I15-1)="",INDEX(Matches!$J$2:$J$25,I15-1)=""),"",IF(J15<=INDEX(Matches!$I$2:$I$25,I15-1)+INDEX(Matches!$J$2:$J$25,I15-1),INDEX(Matches!$A$2:$A$25,I15-1),"")) | B15: =IF(A15="","",IF(J15<=INDEX(Matches!$I$2:$I$25,I15-1),INDEX(Matches!$G$2:$G$25,I15-1),INDEX(Matches!$H$2:$H$25,I15-1))) | C15: =IF(A15="","",COUNTIFS($A$2:A15,A15,$B$2:B15,B15)) | F15: =IF(A15="","",IF(D15="Autogol","",IF(D15="Goal",B15,""))) | G15: =IF(A15="","",IF(D15="","Manca tipo",IF(D15="Goal",IF(E15="","Manca giocatore","OK"),IF(D15="Autogol",IF(E15<>"","Autogol: svuota Player","OK"),"Tipo non valido")))) | H15: =IF(F15="","",VLOOKUP(F15,Validation!$A$2:$B$17,2,FALSE)) | I15: =INT((ROW()-2)/Settings!$B$6)+2 -> 3 | J15: =MOD(ROW()-2,Settings!$B$6)+1 -> 2
A16: =IF(OR(INDEX(Matches!$I$2:$I$25,I16-1)="",INDEX(Matches!$J$2:$J$25,I16-1)=""),"",IF(J16<=INDEX(Matches!$I$2:$I$25,I16-1)+INDEX(Matches!$J$2:$J$25,I16-1),INDEX(Matches!$A$2:$A$25,I16-1),"")) | B16: =IF(A16="","",IF(J16<=INDEX(Matches!$I$2:$I$25,I16-1),INDEX(Matches!$G$2:$G$25,I16-1),INDEX(Matches!$H$2:$H$25,I16-1))) | C16: =IF(A16="","",COUNTIFS($A$2:A16,A16,$B$2:B16,B16)) | F16: =IF(A16="","",IF(D16="Autogol","",IF(D16="Goal",B16,""))) | G16: =IF(A16="","",IF(D16="","Manca tipo",IF(D16="Goal",IF(E16="","Manca giocatore","OK"),IF(D16="Autogol",IF(E16<>"","Autogol: svuota Player","OK"),"Tipo non valido")))) | H16: =IF(F16="","",VLOOKUP(F16,Validation!$A$2:$B$17,2,FALSE)) | I16: =INT((ROW()-2)/Settings!$B$6)+2 -> 3 | J16: =MOD(ROW()-2,Settings!$B$6)+1 -> 3
A17: =IF(OR(INDEX(Matches!$I$2:$I$25,I17-1)="",INDEX(Matches!$J$2:$J$25,I17-1)=""),"",IF(J17<=INDEX(Matches!$I$2:$I$25,I17-1)+INDEX(Matches!$J$2:$J$25,I17-1),INDEX(Matches!$A$2:$A$25,I17-1),"")) | B17: =IF(A17="","",IF(J17<=INDEX(Matches!$I$2:$I$25,I17-1),INDEX(Matches!$G$2:$G$25,I17-1),INDEX(Matches!$H$2:$H$25,I17-1))) | C17: =IF(A17="","",COUNTIFS($A$2:A17,A17,$B$2:B17,B17)) | D17: =IF(A17="","","Goal") | F17: =IF(A17="","",IF(D17="Autogol","",IF(D17="Goal",B17,""))) | G17: =IF(A17="","",IF(D17="","Manca tipo",IF(D17="Goal",IF(E17="","Manca giocatore","OK"),IF(D17="Autogol",IF(E17<>"","Autogol: svuota Player","OK"),"Tipo non valido")))) | H17: =IF(F17="","",VLOOKUP(F17,Validation!$A$2:$B$17,2,FALSE)) | I17: =INT((ROW()-2)/Settings!$B$6)+2 -> 3 | J17: =MOD(ROW()-2,Settings!$B$6)+1 -> 4
A18: =IF(OR(INDEX(Matches!$I$2:$I$25,I18-1)="",INDEX(Matches!$J$2:$J$25,I18-1)=""),"",IF(J18<=INDEX(Matches!$I$2:$I$25,I18-1)+INDEX(Matches!$J$2:$J$25,I18-1),INDEX(Matches!$A$2:$A$25,I18-1),"")) | B18: =IF(A18="","",IF(J18<=INDEX(Matches!$I$2:$I$25,I18-1),INDEX(Matches!$G$2:$G$25,I18-1),INDEX(Matches!$H$2:$H$25,I18-1))) | C18: =IF(A18="","",COUNTIFS($A$2:A18,A18,$B$2:B18,B18)) | D18: =IF(A18="","","Goal") | F18: =IF(A18="","",IF(D18="Autogol","",IF(D18="Goal",B18,""))) | G18: =IF(A18="","",IF(D18="","Manca tipo",IF(D18="Goal",IF(E18="","Manca giocatore","OK"),IF(D18="Autogol",IF(E18<>"","Autogol: svuota Player","OK"),"Tipo non valido")))) | H18: =IF(F18="","",VLOOKUP(F18,Validation!$A$2:$B$17,2,FALSE)) | I18: =INT((ROW()-2)/Settings!$B$6)+2 -> 3 | J18: =MOD(ROW()-2,Settings!$B$6)+1 -> 5
A19: =IF(OR(INDEX(Matches!$I$2:$I$25,I19-1)="",INDEX(Matches!$J$2:$J$25,I19-1)=""),"",IF(J19<=INDEX(Matches!$I$2:$I$25,I19-1)+INDEX(Matches!$J$2:$J$25,I19-1),INDEX(Matches!$A$2:$A$25,I19-1),"")) | B19: =IF(A19="","",IF(J19<=INDEX(Matches!$I$2:$I$25,I19-1),INDEX(Matches!$G$2:$G$25,I19-1),INDEX(Matches!$H$2:$H$25,I19-1))) | C19: =IF(A19="","",COUNTIFS($A$2:A19,A19,$B$2:B19,B19)) | D19: =IF(A19="","","Goal") | F19: =IF(A19="","",IF(D19="Autogol","",IF(D19="Goal",B19,""))) | G19: =IF(A19="","",IF(D19="","Manca tipo",IF(D19="Goal",IF(E19="","Manca giocatore","OK"),IF(D19="Autogol",IF(E19<>"","Autogol: svuota Player","OK"),"Tipo non valido")))) | H19: =IF(F19="","",VLOOKUP(F19,Validation!$A$2:$B$17,2,FALSE)) | I19: =INT((ROW()-2)/Settings!$B$6)+2 -> 3 | J19: =MOD(ROW()-2,Settings!$B$6)+1 -> 6
A20: =IF(OR(INDEX(Matches!$I$2:$I$25,I20-1)="",INDEX(Matches!$J$2:$J$25,I20-1)=""),"",IF(J20<=INDEX(Matches!$I$2:$I$25,I20-1)+INDEX(Matches!$J$2:$J$25,I20-1),INDEX(Matches!$A$2:$A$25,I20-1),"")) | B20: =IF(A20="","",IF(J20<=INDEX(Matches!$I$2:$I$25,I20-1),INDEX(Matches!$G$2:$G$25,I20-1),INDEX(Matches!$H$2:$H$25,I20-1))) | C20: =IF(A20="","",COUNTIFS($A$2:A20,A20,$B$2:B20,B20)) | D20: =IF(A20="","","Goal") | F20: =IF(A20="","",IF(D20="Autogol","",IF(D20="Goal",B20,""))) | G20: =IF(A20="","",IF(D20="","Manca tipo",IF(D20="Goal",IF(E20="","Manca giocatore","OK"),IF(D20="Autogol",IF(E20<>"","Autogol: svuota Player","OK"),"Tipo non valido")))) | H20: =IF(F20="","",VLOOKUP(F20,Validation!$A$2:$B$17,2,FALSE)) | I20: =INT((ROW()-2)/Settings!$B$6)+2 -> 3 | J20: =MOD(ROW()-2,Settings!$B$6)+1 -> 7
A21: =IF(OR(INDEX(Matches!$I$2:$I$25,I21-1)="",INDEX(Matches!$J$2:$J$25,I21-1)=""),"",IF(J21<=INDEX(Matches!$I$2:$I$25,I21-1)+INDEX(Matches!$J$2:$J$25,I21-1),INDEX(Matches!$A$2:$A$25,I21-1),"")) | B21: =IF(A21="","",IF(J21<=INDEX(Matches!$I$2:$I$25,I21-1),INDEX(Matches!$G$2:$G$25,I21-1),INDEX(Matches!$H$2:$H$25,I21-1))) | C21: =IF(A21="","",COUNTIFS($A$2:A21,A21,$B$2:B21,B21)) | D21: =IF(A21="","","Goal") | F21: =IF(A21="","",IF(D21="Autogol","",IF(D21="Goal",B21,""))) | G21: =IF(A21="","",IF(D21="","Manca tipo",IF(D21="Goal",IF(E21="","Manca giocatore","OK"),IF(D21="Autogol",IF(E21<>"","Autogol: svuota Player","OK"),"Tipo non valido")))) | H21: =IF(F21="","",VLOOKUP(F21,Validation!$A$2:$B$17,2,FALSE)) | I21: =INT((ROW()-2)/Settings!$B$6)+2 -> 3 | J21: =MOD(ROW()-2,Settings!$B$6)+1 -> 8
A22: =IF(OR(INDEX(Matches!$I$2:$I$25,I22-1)="",INDEX(Matches!$J$2:$J$25,I22-1)=""),"",IF(J22<=INDEX(Matches!$I$2:$I$25,I22-1)+INDEX(Matches!$J$2:$J$25,I22-1),INDEX(Matches!$A$2:$A$25,I22-1),"")) | B22: =IF(A22="","",IF(J22<=INDEX(Matches!$I$2:$I$25,I22-1),INDEX(Matches!$G$2:$G$25,I22-1),INDEX(Matches!$H$2:$H$25,I22-1))) | C22: =IF(A22="","",COUNTIFS($A$2:A22,A22,$B$2:B22,B22)) | D22: =IF(A22="","","Goal") | F22: =IF(A22="","",IF(D22="Autogol","",IF(D22="Goal",B22,""))) | G22: =IF(A22="","",IF(D22="","Manca tipo",IF(D22="Goal",IF(E22="","Manca giocatore","OK"),IF(D22="Autogol",IF(E22<>"","Autogol: svuota Player","OK"),"Tipo non valido")))) | H22: =IF(F22="","",VLOOKUP(F22,Validation!$A$2:$B$17,2,FALSE)) | I22: =INT((ROW()-2)/Settings!$B$6)+2 -> 3 | J22: =MOD(ROW()-2,Settings!$B$6)+1 -> 9
A23: =IF(OR(INDEX(Matches!$I$2:$I$25,I23-1)="",INDEX(Matches!$J$2:$J$25,I23-1)=""),"",IF(J23<=INDEX(Matches!$I$2:$I$25,I23-1)+INDEX(Matches!$J$2:$J$25,I23-1),INDEX(Matches!$A$2:$A$25,I23-1),"")) | B23: =IF(A23="","",IF(J23<=INDEX(Matches!$I$2:$I$25,I23-1),INDEX(Matches!$G$2:$G$25,I23-1),INDEX(Matches!$H$2:$H$25,I23-1))) | C23: =IF(A23="","",COUNTIFS($A$2:A23,A23,$B$2:B23,B23)) | D23: =IF(A23="","","Goal") | F23: =IF(A23="","",IF(D23="Autogol","",IF(D23="Goal",B23,""))) | G23: =IF(A23="","",IF(D23="","Manca tipo",IF(D23="Goal",IF(E23="","Manca giocatore","OK"),IF(D23="Autogol",IF(E23<>"","Autogol: svuota Player","OK"),"Tipo non valido")))) | H23: =IF(F23="","",VLOOKUP(F23,Validation!$A$2:$B$17,2,FALSE)) | I23: =INT((ROW()-2)/Settings!$B$6)+2 -> 3 | J23: =MOD(ROW()-2,Settings!$B$6)+1 -> 10
A24: =IF(OR(INDEX(Matches!$I$2:$I$25,I24-1)="",INDEX(Matches!$J$2:$J$25,I24-1)=""),"",IF(J24<=INDEX(Matches!$I$2:$I$25,I24-1)+INDEX(Matches!$J$2:$J$25,I24-1),INDEX(Matches!$A$2:$A$25,I24-1),"")) | B24: =IF(A24="","",IF(J24<=INDEX(Matches!$I$2:$I$25,I24-1),INDEX(Matches!$G$2:$G$25,I24-1),INDEX(Matches!$H$2:$H$25,I24-1))) | C24: =IF(A24="","",COUNTIFS($A$2:A24,A24,$B$2:B24,B24)) | D24: =IF(A24="","","Goal") | F24: =IF(A24="","",IF(D24="Autogol","",IF(D24="Goal",B24,""))) | G24: =IF(A24="","",IF(D24="","Manca tipo",IF(D24="Goal",IF(E24="","Manca giocatore","OK"),IF(D24="Autogol",IF(E24<>"","Autogol: svuota Player","OK"),"Tipo non valido")))) | H24: =IF(F24="","",VLOOKUP(F24,Validation!$A$2:$B$17,2,FALSE)) | I24: =INT((ROW()-2)/Settings!$B$6)+2 -> 3 | J24: =MOD(ROW()-2,Settings!$B$6)+1 -> 11
A25: =IF(OR(INDEX(Matches!$I$2:$I$25,I25-1)="",INDEX(Matches!$J$2:$J$25,I25-1)=""),"",IF(J25<=INDEX(Matches!$I$2:$I$25,I25-1)+INDEX(Matches!$J$2:$J$25,I25-1),INDEX(Matches!$A$2:$A$25,I25-1),"")) | B25: =IF(A25="","",IF(J25<=INDEX(Matches!$I$2:$I$25,I25-1),INDEX(Matches!$G$2:$G$25,I25-1),INDEX(Matches!$H$2:$H$25,I25-1))) | C25: =IF(A25="","",COUNTIFS($A$2:A25,A25,$B$2:B25,B25)) | D25: =IF(A25="","","Goal") | F25: =IF(A25="","",IF(D25="Autogol","",IF(D25="Goal",B25,""))) | G25: =IF(A25="","",IF(D25="","Manca tipo",IF(D25="Goal",IF(E25="","Manca giocatore","OK"),IF(D25="Autogol",IF(E25<>"","Autogol: svuota Player","OK"),"Tipo non valido")))) | H25: =IF(F25="","",VLOOKUP(F25,Validation!$A$2:$B$17,2,FALSE)) | I25: =INT((ROW()-2)/Settings!$B$6)+2 -> 3 | J25: =MOD(ROW()-2,Settings!$B$6)+1 -> 12
A26: =IF(OR(INDEX(Matches!$I$2:$I$25,I26-1)="",INDEX(Matches!$J$2:$J$25,I26-1)=""),"",IF(J26<=INDEX(Matches!$I$2:$I$25,I26-1)+INDEX(Matches!$J$2:$J$25,I26-1),INDEX(Matches!$A$2:$A$25,I26-1),"")) -> M03 | B26: =IF(A26="","",IF(J26<=INDEX(Matches!$I$2:$I$25,I26-1),INDEX(Matches!$G$2:$G$25,I26-1),INDEX(Matches!$H$2:$H$25,I26-1))) -> Vecchie Glorie Rovigo | C26: =IF(A26="","",COUNTIFS($A$2:A26,A26,$B$2:B26,B26)) -> 1 | D26: =IF(A26="","","Goal") -> Goal | E26: 3 - MATTEO ZAMBERLAN | F26: =IF(A26="","",IF(D26="Autogol","",IF(D26="Goal",B26,""))) -> Vecchie Glorie Rovigo | G26: =IF(A26="","",IF(D26="","Manca tipo",IF(D26="Goal",IF(E26="","Manca giocatore","OK"),IF(D26="Autogol",IF(E26<>"","Autogol: svuota Player","OK"),"Tipo non valido")))) -> OK | H26: =IF(F26="","",VLOOKUP(F26,Validation!$A$2:$B$17,2,FALSE)) -> Validation!$H$2:$H$31 | I26: =INT((ROW()-2)/Settings!$B$6)+2 -> 4 | J26: =MOD(ROW()-2,Settings!$B$6)+1 -> 1
A27: =IF(OR(INDEX(Matches!$I$2:$I$25,I27-1)="",INDEX(Matches!$J$2:$J$25,I27-1)=""),"",IF(J27<=INDEX(Matches!$I$2:$I$25,I27-1)+INDEX(Matches!$J$2:$J$25,I27-1),INDEX(Matches!$A$2:$A$25,I27-1),"")) -> M03 | B27: =IF(A27="","",IF(J27<=INDEX(Matches!$I$2:$I$25,I27-1),INDEX(Matches!$G$2:$G$25,I27-1),INDEX(Matches!$H$2:$H$25,I27-1))) -> Vecchie Glorie Rovigo | C27: =IF(A27="","",COUNTIFS($A$2:A27,A27,$B$2:B27,B27)) -> 2 | D27: =IF(A27="","","Goal") -> Goal | E27: 3 - MATTEO ZAMBERLAN | F27: =IF(A27="","",IF(D27="Autogol","",IF(D27="Goal",B27,""))) -> Vecchie Glorie Rovigo | G27: =IF(A27="","",IF(D27="","Manca tipo",IF(D27="Goal",IF(E27="","Manca giocatore","OK"),IF(D27="Autogol",IF(E27<>"","Autogol: svuota Player","OK"),"Tipo non valido")))) -> OK | H27: =IF(F27="","",VLOOKUP(F27,Validation!$A$2:$B$17,2,FALSE)) -> Validation!$H$2:$H$31 | I27: =INT((ROW()-2)/Settings!$B$6)+2 -> 4 | J27: =MOD(ROW()-2,Settings!$B$6)+1 -> 2
A28: =IF(OR(INDEX(Matches!$I$2:$I$25,I28-1)="",INDEX(Matches!$J$2:$J$25,I28-1)=""),"",IF(J28<=INDEX(Matches!$I$2:$I$25,I28-1)+INDEX(Matches!$J$2:$J$25,I28-1),INDEX(Matches!$A$2:$A$25,I28-1),"")) -> M03 | B28: =IF(A28="","",IF(J28<=INDEX(Matches!$I$2:$I$25,I28-1),INDEX(Matches!$G$2:$G$25,I28-1),INDEX(Matches!$H$2:$H$25,I28-1))) -> Vecchie Glorie Rovigo | C28: =IF(A28="","",COUNTIFS($A$2:A28,A28,$B$2:B28,B28)) -> 3 | D28: =IF(A28="","","Goal") -> Goal | E28: 3 - MATTEO ZAMBERLAN | F28: =IF(A28="","",IF(D28="Autogol","",IF(D28="Goal",B28,""))) -> Vecchie Glorie Rovigo | G28: =IF(A28="","",IF(D28="","Manca tipo",IF(D28="Goal",IF(E28="","Manca giocatore","OK"),IF(D28="Autogol",IF(E28<>"","Autogol: svuota Player","OK"),"Tipo non valido")))) -> OK | H28: =IF(F28="","",VLOOKUP(F28,Validation!$A$2:$B$17,2,FALSE)) -> Validation!$H$2:$H$31 | I28: =INT((ROW()-2)/Settings!$B$6)+2 -> 4 | J28: =MOD(ROW()-2,Settings!$B$6)+1 -> 3
A29: =IF(OR(INDEX(Matches!$I$2:$I$25,I29-1)="",INDEX(Matches!$J$2:$J$25,I29-1)=""),"",IF(J29<=INDEX(Matches!$I$2:$I$25,I29-1)+INDEX(Matches!$J$2:$J$25,I29-1),INDEX(Matches!$A$2:$A$25,I29-1),"")) -> M03 | B29: =IF(A29="","",IF(J29<=INDEX(Matches!$I$2:$I$25,I29-1),INDEX(Matches!$G$2:$G$25,I29-1),INDEX(Matches!$H$2:$H$25,I29-1))) -> Vecchie Glorie Rovigo | C29: =IF(A29="","",COUNTIFS($A$2:A29,A29,$B$2:B29,B29)) -> 4 | D29: =IF(A29="","","Goal") -> Goal | E29: 10 - DAVIDE ZAGHI (C) | F29: =IF(A29="","",IF(D29="Autogol","",IF(D29="Goal",B29,""))) -> Vecchie Glorie Rovigo | G29: =IF(A29="","",IF(D29="","Manca tipo",IF(D29="Goal",IF(E29="","Manca giocatore","OK"),IF(D29="Autogol",IF(E29<>"","Autogol: svuota Player","OK"),"Tipo non valido")))) -> OK | H29: =IF(F29="","",VLOOKUP(F29,Validation!$A$2:$B$17,2,FALSE)) -> Validation!$H$2:$H$31 | I29: =INT((ROW()-2)/Settings!$B$6)+2 -> 4 | J29: =MOD(ROW()-2,Settings!$B$6)+1 -> 4
