Workbook

Sheet README
A1: 12 ORE BOSARO 2026 — Tournament Manager
A3: Uso rapido: 1) inserisci risultati in Matches, colonne HomeGoals/AwayGoals/PenaltyWinner; 2) vai su Goals e completa solo le righe rosse con GoalType e Player; 3) Standings, TopScorers ed Export si aggiornano automaticamente.
A5: Punti vittoria | B5: 3
A6: Punti vittoria ai rigori | B6: 2
A7: Punti sconfitta ai rigori | B7: 1
A8: Punti sconfitta | B8: 0
A9: Ordinamento classifica | B9: Punti, H2H manuale, differenza reti, gol fatti
A10: Autogol | B10: Non associato ad alcun giocatore e non conteggiato nei marcatori
A11: Fonte rose | B11: Squadre_iscritte(1).pdf
A12: Fonte calendario | B12: calendario_partite.pdf / gironi.pdf / fase_finale.pdf
A14: Modifiche v4 | B14: Export include anche marcatori aggregati per partita e tabella normalizzata match_goals.
A15: PenaltyWinner | B15: Nel foglio Matches il vincitore ai rigori è vincolato a squadra casa/trasferta della riga.
A16: GoalType | B16: Nel foglio Goals il tipo è Goal di default; cambia in Autogol solo se serve e lascia Player vuoto.
A17: Export sito | B17: Usa sezione matches per risultati + marcatori aggregati, oppure match_goals per dati normalizzati.

Sheet Settings
A1: Setting | B1: Value
A2: WinPoints | B2: 3
A3: PenaltyWinPoints | B3: 2
A4: PenaltyLossPoints | B4: 1
A5: LossPoints | B5: 0
A6: MaxGoalSlotsPerMatch | B6: 12

Sheet Teams
A1: TeamID | B1: Group | C1: TeamName | D1: Players
A2: T01 | B2: A | C2: Fatine FC | D2: 10
A3: T02 | B3: A | C3: FC Internazionale Rovigo | D3: 10
A4: T03 | B4: A | C4: Moviola Utd | D4: 12
A5: T04 | B5: A | C5: Astolfi Impianti Elettrici | D5: 9
A6: T05 | B6: B | C6: Totani | D6: 9
A7: T06 | B7: B | C7: Vecchie Glorie Rovigo | D7: 11
A8: T07 | B8: B | C8: AS Bancatore | D8: 11
A9: T08 | B9: B | C9: Beverton | D9: 6
A10: T09 | B10: C | C10: Leoni di Ricky | D10: 8
A11: T10 | B11: C | C11: Pink 5ive | D11: 10
A12: T11 | B12: C | C12: Barrio Boys | D12: 10
A13: T12 | B13: C | C13: Cani | D13: 10
... A17: T16 | B17: D | C17: Piadineria la Salsiccia | D17: 10

Sheet Players
A1: PlayerID | B1: TeamID | C1: TeamName | D1: ShirtNumber | E1: PlayerName | F1: Captain | G1: DisplayName
A2: P001 | B2: T01 | C2: Fatine FC | D2: 1 | E2: PIETRO SEGATO | F2: No | G2: 1 - PIETRO SEGATO
A3: P002 | B3: T01 | C3: Fatine FC | D3: 4 | E3: GIOVANNI BALLO | F3: No | G3: 4 - GIOVANNI BALLO
A4: P003 | B4: T01 | C4: Fatine FC | D4: 5 | E4: DANIELE MARZOLLA | F4: No | G4: 5 - DANIELE MARZOLLA
A5: P004 | B5: T01 | C5: Fatine FC | D5: 7 | E5: NICHOLAS MILAN | F5: No | G5: 7 - NICHOLAS MILAN
A6: P005 | B6: T01 | C6: Fatine FC | D6: 8 | E6: ALESSIO MILAN | F6: No | G6: 8 - ALESSIO MILAN
A7: P006 | B7: T01 | C7: Fatine FC | D7: 10 | E7: LUCA MARINI | F7: No | G7: 10 - LUCA MARINI
A8: P007 | B8: T01 | C8: Fatine FC | D8: 11 | E8: DAVIDE GHIRARDI | F8: No | G8: 11 - DAVIDE GHIRARDI
A9: P008 | B9: T01 | C9: Fatine FC | D9: 23 | E9: NICOLA MARINI | F9: Yes | G9: 23 - NICOLA MARINI (C)
A10: P009 | B10: T01 | C10: Fatine FC | D10: 69 | E10: LUCA ROSSETTO | F10: No | G10: 69 - LUCA ROSSETTO
A11: P010 | B11: T01 | C11: Fatine FC | D11: 90 | E11: MANUEL MEDEA | F11: No | G11: 90 - MANUEL MEDEA
A12: P011 | B12: T02 | C12: FC Internazionale Rovigo | E12: BOGDAN ATAMANYUK | F12: No | G12: BOGDAN ATAMANYUK
A13: P012 | B13: T02 | C13: FC Internazionale Rovigo | E13: IVAN DENIS SHEVERAK | F13: No | G13: IVAN DENIS SHEVERAK
A14: P013 | B14: T02 | C14: FC Internazionale Rovigo | E14: MOHAMED IAICH | F14: No | G14: MOHAMED IAICH
A15: P014 | B15: T02 | C15: FC Internazionale Rovigo | E15: NICOLÒ ANDOLFO | F15: No | G15: NICOLÒ ANDOLFO
A16: P015 | B16: T02 | C16: FC Internazionale Rovigo | E16: AHMED ZOUZAF | F16: No | G16: AHMED ZOUZAF
A17: P016 | B17: T02 | C17: FC Internazionale Rovigo | E17: YOUSSEF IAICH | F17: No | G17: YOUSSEF IAICH
A18: P017 | B18: T02 | C18: FC Internazionale Rovigo | E18: HAMZA AGRIBI | F18: Yes | G18: HAMZA AGRIBI (C)
A19: P018 | B19: T02 | C19: FC Internazionale Rovigo | E19: KHALID BENNOUNE | F19: No | G19: KHALID BENNOUNE
A20: P019 | B20: T02 | C20: FC Internazionale Rovigo | E20: YASSINE SOHAYB | F20: No | G20: YASSINE SOHAYB
A21: P020 | B21: T02 | C21: FC Internazionale Rovigo | E21: ABDESSAMAD BAGHROUCH | F21: No | G21: ABDESSAMAD BAGHROUCH
A22: P021 | B22: T03 | C22: Moviola Utd | E22: FILIPPO ZANFORLIN | F22: No | G22: FILIPPO ZANFORLIN
A23: P022 | B23: T03 | C23: Moviola Utd | E23: MICHAEL STRENGHETTO | F23: Yes | G23: MICHAEL STRENGHETTO (C)
... A33: P032 | B33: T03 | C33: Moviola Utd | E33: MATTEO SENO | F33: No | G33: MATTEO SENO
A34: P033 | B34: T04 | C34: Astolfi Impianti Elettrici | D34: 1 | E34: NICOLAS ANDRIOTTO | F34: No | G34: 1 - NICOLAS ANDRIOTTO
A35: P034 | B35: T04 | C35: Astolfi Impianti Elettrici | D35: 4 | E35: GIANLUCA PAVAN | F35: No | G35: 4 - GIANLUCA PAVAN
A36: P035 | B36: T04 | C36: Astolfi Impianti Elettrici | D36: 6 | E36: NICOLA CAVALLIERI | F36: No | G36: 6 - NICOLA CAVALLIERI
A37: P036 | B37: T04 | C37: Astolfi Impianti Elettrici | D37: 7 | E37: ALBAN AHMATI | F37: No | G37: 7 - ALBAN AHMATI
A38: P037 | B38: T04 | C38: Astolfi Impianti Elettrici | D38: 8 | E38: MARCO PREVIATO | F38: No | G38: 8 - MARCO PREVIATO
A39: P038 | B39: T04 | C39: Astolfi Impianti Elettrici | D39: 9 | E39: LUCA SIMEONE | F39: No | G39: 9 - LUCA SIMEONE
A40: P039 | B40: T04 | C40: Astolfi Impianti Elettrici | D40: 10 | E40: ELIA NAGLIERI | F40: No | G40: 10 - ELIA NAGLIERI
A41: P040 | B41: T04 | C41: Astolfi Impianti Elettrici | D41: 11 | E41: FILIPPO ZANINI | F41: Yes | G41: 11 - FILIPPO ZANINI (C)
A42: P041 | B42: T04 | C42: Astolfi Impianti Elettrici | D42: 14 | E42: ALBERTO MUNERATO | F42: No | G42: 14 - ALBERTO MUNERATO
A43: P042 | B43: T05 | C43: Totani | D43: 5 | E43: DANIEL TARGA | F43: No | G43: 5 - DANIEL TARGA
A44: P043 | B44: T05 | C44: Totani | D44: 6 | E44: RICCARDO DAVÌ | F44: No | G44: 6 - RICCARDO DAVÌ
A45: P044 | B45: T05 | C45: Totani | D45: 7 | E45: RICCARDO SANTARATO | F45: No | G45: 7 - RICCARDO SANTARATO
... A51: P050 | B51: T05 | C51: Totani | D51: 71 | E51: DANIELE SECCO | F51: No | G51: 71 - DANIELE SECCO
A52: P051 | B52: T06 | C52: Vecchie Glorie Rovigo | E52: DAVIDE ZAGHI | F52: No | G52: DAVIDE ZAGHI
A53: P052 | B53: T06 | C53: Vecchie Glorie Rovigo | E53: JACOPO VOLTOLINA | F53: No | G53: JACOPO VOLTOLINA
A54: P053 | B54: T06 | C54: Vecchie Glorie Rovigo | E54: MATTEO ZAMBERLAN | F54: No | G54: MATTEO ZAMBERLAN
...

Sheet Matches
A1: MatchID | B1: Stage | C1: Group | D1: Round | E1: Field | F1: Time | G1: HomeTeam | H1: AwayTeam | I1: HomeGoals | J1: AwayGoals | K1: PenaltyWinner | L1: Status | M1: HomePoints | N1: AwayPoints | O1: Winner | P1: ScoreLabel
A2: M01 | B2: Group | C2: D | D2: 1 | E2: 1 | F2: 14:15 | G2: All Blacks | H2: Boldò Glimt | I2: 1 | J2: 0 | L2: =IF(OR(I2="",J2=""),"Pending",IF(I2=J2,IF(K2="","Needs penalty winner","Complete"),"Complete")) -> Complete | M2: =IF(OR(I2="",J2=""),"",IF(I2>J2,Settings!$B$2,IF(I2<J2,Settings!$B$5,IF(K2=G2,Settings!$B$3,IF(K2=H2,Settings!$B$4,""))))) -> 3 | N2: =IF(OR(I2="",J2=""),"",IF(J2>I2,Settings!$B$2,IF(J2<I2,Settings!$B$5,IF(K2=H2,Settings!$B$3,IF(K2=G2,Settings!$B$4,""))))) -> 0 | O2: =IF(OR(I2="",J2=""),"",IF(I2>J2,G2,IF(J2>I2,H2,K2))) -> All Blacks | P2: =IF(OR(I2="",J2=""),"",G2&" "&I2&" - "&J2&" "&H2&IF(K2<>""," (rigori: "&K2&")","")) -> All Blacks 1 - 0 Boldò Glimt
A3: M02 | B3: Group | C3: D | D3: 1 | E3: 2 | F3: 14:15 | G3: Coca Juniors | H3: Piadineria la Salsiccia | L3: =IF(OR(I3="",J3=""),"Pending",IF(I3=J3,IF(K3="","Needs penalty winner","Complete"),"Complete")) -> Pending | M3: =IF(OR(I3="",J3=""),"",IF(I3>J3,Settings!$B$2,IF(I3<J3,Settings!$B$5,IF(K3=G3,Settings!$B$3,IF(K3=H3,Settings!$B$4,""))))) | N3: =IF(OR(I3="",J3=""),"",IF(J3>I3,Settings!$B$2,IF(J3<I3,Settings!$B$5,IF(K3=H3,Settings!$B$3,IF(K3=G3,Settings!$B$4,""))))) | O3: =IF(OR(I3="",J3=""),"",IF(I3>J3,G3,IF(J3>I3,H3,K3))) | P3: =IF(OR(I3="",J3=""),"",G3&" "&I3&" - "&J3&" "&H3&IF(K3<>""," (rigori: "&K3&")",""))
A4: M03 | B4: Group | C4: B | D4: 1 | E4: 3 (S) | F4: 14:15 | G4: Totani | H4: Vecchie Glorie Rovigo | L4: =IF(OR(I4="",J4=""),"Pending",IF(I4=J4,IF(K4="","Needs penalty winner","Complete"),"Complete")) -> Pending | M4: =IF(OR(I4="",J4=""),"",IF(I4>J4,Settings!$B$2,IF(I4<J4,Settings!$B$5,IF(K4=G4,Settings!$B$3,IF(K4=H4,Settings!$B$4,""))))) | N4: =IF(OR(I4="",J4=""),"",IF(J4>I4,Settings!$B$2,IF(J4<I4,Settings!$B$5,IF(K4=H4,Settings!$B$3,IF(K4=G4,Settings!$B$4,""))))) | O4: =IF(OR(I4="",J4=""),"",IF(I4>J4,G4,IF(J4>I4,H4,K4))) | P4: =IF(OR(I4="",J4=""),"",G4&" "&I4&" - "&J4&" "&H4&IF(K4<>""," (rigori: "&K4&")",""))
A5: M04 | B5: Group | C5: C | D5: 1 | E5: 1 | F5: 14:45 | G5: Leoni di Ricky | H5: Pink 5ive | L5: =IF(OR(I5="",J5=""),"Pending",IF(I5=J5,IF(K5="","Needs penalty winner","Complete"),"Complete")) -> Pending | M5: =IF(OR(I5="",J5=""),"",IF(I5>J5,Settings!$B$2,IF(I5<J5,Settings!$B$5,IF(K5=G5,Settings!$B$3,IF(K5=H5,Settings!$B$4,""))))) | N5: =IF(OR(I5="",J5=""),"",IF(J5>I5,Settings!$B$2,IF(J5<I5,Settings!$B$5,IF(K5=H5,Settings!$B$3,IF(K5=G5,Settings!$B$4,""))))) | O5: =IF(OR(I5="",J5=""),"",IF(I5>J5,G5,IF(J5>I5,H5,K5))) | P5: =IF(OR(I5="",J5=""),"",G5&" "&I5&" - "&J5&" "&H5&IF(K5<>""," (rigori: "&K5&")",""))
A6: M05 | B6: Group | C6: C | D6: 1 | E6: 2 | F6: 14:45 | G6: Barrio Boys | H6: Cani | L6: =IF(OR(I6="",J6=""),"Pending",IF(I6=J6,IF(K6="","Needs penalty winner","Complete"),"Complete")) -> Pending | M6: =IF(OR(I6="",J6=""),"",IF(I6>J6,Settings!$B$2,IF(I6<J6,Settings!$B$5,IF(K6=G6,Settings!$B$3,IF(K6=H6,Settings!$B$4,""))))) | N6: =IF(OR(I6="",J6=""),"",IF(J6>I6,Settings!$B$2,IF(J6<I6,Settings!$B$5,IF(K6=H6,Settings!$B$3,IF(K6=G6,Settings!$B$4,""))))) | O6: =IF(OR(I6="",J6=""),"",IF(I6>J6,G6,IF(J6>I6,H6,K6))) | P6: =IF(OR(I6="",J6=""),"",G6&" "&I6&" - "&J6&" "&H6&IF(K6<>""," (rigori: "&K6&")",""))
A7: M06 | B7: Group | C7: B | D7: 1 | E7: 3 (S) | F7: 14:45 | G7: AS Bancatore | H7: Beverton | L7: =IF(OR(I7="",J7=""),"Pending",IF(I7=J7,IF(K7="","Needs penalty winner","Complete"),"Complete")) -> Pending | M7: =IF(OR(I7="",J7=""),"",IF(I7>J7,Settings!$B$2,IF(I7<J7,Settings!$B$5,IF(K7=G7,Settings!$B$3,IF(K7=H7,Settings!$B$4,""))))) | N7: =IF(OR(I7="",J7=""),"",IF(J7>I7,Settings!$B$2,IF(J7<I7,Settings!$B$5,IF(K7=H7,Settings!$B$3,IF(K7=G7,Settings!$B$4,""))))) | O7: =IF(OR(I7="",J7=""),"",IF(I7>J7,G7,IF(J7>I7,H7,K7))) | P7: =IF(OR(I7="",J7=""),"",G7&" "&I7&" - "&J7&" "&H7&IF(K7<>""," (rigori: "&K7&")",""))
A8: M07 | B8: Group | C8: A | D8: 1 | E8: 1 | F8: 15:15 | G8: Fatine FC | H8: FC Internazionale Rovigo | L8: =IF(OR(I8="",J8=""),"Pending",IF(I8=J8,IF(K8="","Needs penalty winner","Complete"),"Complete")) -> Pending | M8: =IF(OR(I8="",J8=""),"",IF(I8>J8,Settings!$B$2,IF(I8<J8,Settings!$B$5,IF(K8=G8,Settings!$B$3,IF(K8=H8,Settings!$B$4,""))))) | N8: =IF(OR(I8="",J8=""),"",IF(J8>I8,Settings!$B$2,IF(J8<I8,Settings!$B$5,IF(K8=H8,Settings!$B$3,IF(K8=G8,Settings!$B$4,""))))) | O8: =IF(OR(I8="",J8=""),"",IF(I8>J8,G8,IF(J8>I8,H8,K8))) | P8: =IF(OR(I8="",J8=""),"",G8&" "&I8&" - "&J8&" "&H8&IF(K8<>""," (rigori: "&K8&")",""))
A9: M08 | B9: Group | C9: A | D9: 1 | E9: 2 | F9: 15:15 | G9: Moviola Utd | H9: Astolfi Impianti Elettrici | L9: =IF(OR(I9="",J9=""),"Pending",IF(I9=J9,IF(K9="","Needs penalty winner","Complete"),"Complete")) -> Pending | M9: =IF(OR(I9="",J9=""),"",IF(I9>J9,Settings!$B$2,IF(I9<J9,Settings!$B$5,IF(K9=G9,Settings!$B$3,IF(K9=H9,Settings!$B$4,""))))) | N9: =IF(OR(I9="",J9=""),"",IF(J9>I9,Settings!$B$2,IF(J9<I9,Settings!$B$5,IF(K9=H9,Settings!$B$3,IF(K9=G9,Settings!$B$4,""))))) | O9: =IF(OR(I9="",J9=""),"",IF(I9>J9,G9,IF(J9>I9,H9,K9))) | P9: =IF(OR(I9="",J9=""),"",G9&" "&I9&" - "&J9&" "&H9&IF(K9<>""," (rigori: "&K9&")",""))
A10: M09 | B10: Group | C10: D | D10: 2 | E10: 3 (S) | F10: 15:15 | G10: All Blacks | H10: Coca Juniors | L10: =IF(OR(I10="",J10=""),"Pending",IF(I10=J10,IF(K10="","Needs penalty winner","Complete"),"Complete")) -> Pending | M10: =IF(OR(I10="",J10=""),"",IF(I10>J10,Settings!$B$2,IF(I10<J10,Settings!$B$5,IF(K10=G10,Settings!$B$3,IF(K10=H10,Settings!$B$4,""))))) | N10: =IF(OR(I10="",J10=""),"",IF(J10>I10,Settings!$B$2,IF(J10<I10,Settings!$B$5,IF(K10=H10,Settings!$B$3,IF(K10=G10,Settings!$B$4,""))))) | O10: =IF(OR(I10="",J10=""),"",IF(I10>J10,G10,IF(J10>I10,H10,K10))) | P10: =IF(OR(I10="",J10=""),"",G10&" "&I10&" - "&J10&" "&H10&IF(K10<>""," (rigori: "&K10&")",""))
A11: M10 | B11: Group | C11: B | D11: 2 | E11: 1 | F11: 15:45 | G11: Totani | H11: AS Bancatore | L11: =IF(OR(I11="",J11=""),"Pending",IF(I11=J11,IF(K11="","Needs penalty winner","Complete"),"Complete")) -> Pending | M11: =IF(OR(I11="",J11=""),"",IF(I11>J11,Settings!$B$2,IF(I11<J11,Settings!$B$5,IF(K11=G11,Settings!$B$3,IF(K11=H11,Settings!$B$4,""))))) | N11: =IF(OR(I11="",J11=""),"",IF(J11>I11,Settings!$B$2,IF(J11<I11,Settings!$B$5,IF(K11=H11,Settings!$B$3,IF(K11=G11,Settings!$B$4,""))))) | O11: =IF(OR(I11="",J11=""),"",IF(I11>J11,G11,IF(J11>I11,H11,K11))) | P11: =IF(OR(I11="",J11=""),"",G11&" "&I11&" - "&J11&" "&H11&IF(K11<>""," (rigori: "&K11&")",""))
A12: M11 | B12: Group | C12: B | D12: 2 | E12: 2 | F12: 15:45 | G12: Vecchie Glorie Rovigo | H12: Beverton | L12: =IF(OR(I12="",J12=""),"Pending",IF(I12=J12,IF(K12="","Needs penalty winner","Complete"),"Complete")) -> Pending | M12: =IF(OR(I12="",J12=""),"",IF(I12>J12,Settings!$B$2,IF(I12<J12,Settings!$B$5,IF(K12=G12,Settings!$B$3,IF(K12=H12,Settings!$B$4,""))))) | N12: =IF(OR(I12="",J12=""),"",IF(J12>I12,Settings!$B$2,IF(J12<I12,Settings!$B$5,IF(K12=H12,Settings!$B$3,IF(K12=G12,Settings!$B$4,""))))) | O12: =IF(OR(I12="",J12=""),"",IF(I12>J12,G12,IF(J12>I12,H12,K12))) | P12: =IF(OR(I12="",J12=""),"",G12&" "&I12&" - "&J12&" "&H12&IF(K12<>""," (rigori: "&K12&")",""))
A13: M12 | B13: Group | C13: D | D13: 2 | E13: 3 (S) | F13: 15:45 | G13: Boldò Glimt | H13: Piadineria la Salsiccia | L13: =IF(OR(I13="",J13=""),"Pending",IF(I13=J13,IF(K13="","Needs penalty winner","Complete"),"Complete")) -> Pending | M13: =IF(OR(I13="",J13=""),"",IF(I13>J13,Settings!$B$2,IF(I13<J13,Settings!$B$5,IF(K13=G13,Settings!$B$3,IF(K13=H13,Settings!$B$4,""))))) | N13: =IF(OR(I13="",J13=""),"",IF(J13>I13,Settings!$B$2,IF(J13<I13,Settings!$B$5,IF(K13=H13,Settings!$B$3,IF(K13=G13,Settings!$B$4,""))))) | O13: =IF(OR(I13="",J13=""),"",IF(I13>J13,G13,IF(J13>I13,H13,K13))) | P13: =IF(OR(I13="",J13=""),"",G13&" "&I13&" - "&J13&" "&H13&IF(K13<>""," (rigori: "&K13&")",""))
A14: M13 | B14: Group | C14: C | D14: 2 | E14: 1 | F14: 16:30 | G14: Leoni di Ricky | H14: Barrio Boys | L14: =IF(OR(I14="",J14=""),"Pending",IF(I14=J14,IF(K14="","Needs penalty winner","Complete"),"Complete")) -> Pending | M14: =IF(OR(I14="",J14=""),"",IF(I14>J14,Settings!$B$2,IF(I14<J14,Settings!$B$5,IF(K14=G14,Settings!$B$3,IF(K14=H14,Settings!$B$4,""))))) | N14: =IF(OR(I14="",J14=""),"",IF(J14>I14,Settings!$B$2,IF(J14<I14,Settings!$B$5,IF(K14=H14,Settings!$B$3,IF(K14=G14,Settings!$B$4,""))))) | O14: =IF(OR(I14="",J14=""),"",IF(I14>J14,G14,IF(J14>I14,H14,K14))) | P14: =IF(OR(I14="",J14=""),"",G14&" "&I14&" - "&J14&" "&H14&IF(K14<>""," (rigori: "&K14&")",""))
... A25: M24 | B25: Group | C25: C | D25: 3 | E25: 3 (S) | F25: 18:00 | G25: Pink 5ive | H25: Barrio Boys | L25: =IF(OR(I25="",J25=""),"Pending",IF(I25=J25,IF(K25="","Needs penalty winner","Complete"),"Complete")) -> Pending | M25: =IF(OR(I25="",J25=""),"",IF(I25>J25,Settings!$B$2,IF(I25<J25,Settings!$B$5,IF(K25=G25,Settings!$B$3,IF(K25=H25,Settings!$B$4,""))))) | N25: =IF(OR(I25="",J25=""),"",IF(J25>I25,Settings!$B$2,IF(J25<I25,Settings!$B$5,IF(K25=H25,Settings!$B$3,IF(K25=G25,Settings!$B$4,""))))) | O25: =IF(OR(I25="",J25=""),"",IF(I25>J25,G25,IF(J25>I25,H25,K25))) | P25: =IF(OR(I25="",J25=""),"",G25&" "&I25&" - "&J25&" "&H25&IF(K25<>""," (rigori: "&K25&")",""))

Sheet Goals
A1: MatchID | B1: GoalForTeam | C1: GoalSlot | D1: GoalType | E1: Player | F1: ScorerTeam | G1: Status | H1: PlayerListRange | I1: MatchRow | J1: Slot | K1: Note
A2: =IF(OR(INDEX(Matches!$I$2:$I$25,I2-1)="",INDEX(Matches!$J$2:$J$25,I2-1)=""),"",IF(J2<=INDEX(Matches!$I$2:$I$25,I2-1)+INDEX(Matches!$J$2:$J$25,I2-1),INDEX(Matches!$A$2:$A$25,I2-1),"")) -> M01 | B2: =IF(A2="","",IF(J2<=INDEX(Matches!$I$2:$I$25,I2-1),INDEX(Matches!$G$2:$G$25,I2-1),INDEX(Matches!$H$2:$H$25,I2-1))) -> All Blacks | C2: =IF(A2="","",COUNTIFS($A$2:A2,A2,$B$2:B2,B2)) -> 1 | D2: Goal | E2: 4 - STEFANO BRAGHIN | F2: =IF(A2="","",IF(D2="Autogol","",IF(D2="Goal",B2,""))) -> All Blacks | G2: =IF(A2="","",IF(D2="","Manca tipo",IF(D2="Goal",IF(E2="","Manca giocatore","OK"),IF(D2="Autogol",IF(E2<>"","Autogol: svuota Player","OK"),"Tipo non valido")))) -> OK | H2: =IF(F2="","",VLOOKUP(F2,Validation!$A$2:$B$17,2,FALSE)) -> Validation!$O$2:$O$12 | I2: =INT((ROW()-2)/Settings!$B$6)+2 -> 2 | J2: =MOD(ROW()-2,Settings!$B$6)+1 -> 1 | K2: Autogol: lasciare Player vuoto; non viene conteggiato nella classifica marcatori.
A3: =IF(OR(INDEX(Matches!$I$2:$I$25,I3-1)="",INDEX(Matches!$J$2:$J$25,I3-1)=""),"",IF(J3<=INDEX(Matches!$I$2:$I$25,I3-1)+INDEX(Matches!$J$2:$J$25,I3-1),INDEX(Matches!$A$2:$A$25,I3-1),"")) | B3: =IF(A3="","",IF(J3<=INDEX(Matches!$I$2:$I$25,I3-1),INDEX(Matches!$G$2:$G$25,I3-1),INDEX(Matches!$H$2:$H$25,I3-1))) | C3: =IF(A3="","",COUNTIFS($A$2:A3,A3,$B$2:B3,B3)) | F3: =IF(A3="","",IF(D3="Autogol","",IF(D3="Goal",B3,""))) | G3: =IF(A3="","",IF(D3="","Manca tipo",IF(D3="Goal",IF(E3="","Manca giocatore","OK"),IF(D3="Autogol",IF(E3<>"","Autogol: svuota Player","OK"),"Tipo non valido")))) | H3: =IF(F3="","",VLOOKUP(F3,Validation!$A$2:$B$17,2,FALSE)) | I3: =INT((ROW()-2)/Settings!$B$6)+2 -> 2 | J3: =MOD(ROW()-2,Settings!$B$6)+1 -> 2
A4: =IF(OR(INDEX(Matches!$I$2:$I$25,I4-1)="",INDEX(Matches!$J$2:$J$25,I4-1)=""),"",IF(J4<=INDEX(Matches!$I$2:$I$25,I4-1)+INDEX(Matches!$J$2:$J$25,I4-1),INDEX(Matches!$A$2:$A$25,I4-1),"")) | B4: =IF(A4="","",IF(J4<=INDEX(Matches!$I$2:$I$25,I4-1),INDEX(Matches!$G$2:$G$25,I4-1),INDEX(Matches!$H$2:$H$25,I4-1))) | C4: =IF(A4="","",COUNTIFS($A$2:A4,A4,$B$2:B4,B4)) | F4: =IF(A4="","",IF(D4="Autogol","",IF(D4="Goal",B4,""))) | G4: =IF(A4="","",IF(D4="","Manca tipo",IF(D4="Goal",IF(E4="","Manca giocatore","OK"),IF(D4="Autogol",IF(E4<>"","Autogol: svuota Player","OK"),"Tipo non valido")))) | H4: =IF(F4="","",VLOOKUP(F4,Validation!$A$2:$B$17,2,FALSE)) | I4: =INT((ROW()-2)/Settings!$B$6)+2 -> 2 | J4: =MOD(ROW()-2,Settings!$B$6)+1 -> 3
A5: =IF(OR(INDEX(Matches!$I$2:$I$25,I5-1)="",INDEX(Matches!$J$2:$J$25,I5-1)=""),"",IF(J5<=INDEX(Matches!$I$2:$I$25,I5-1)+INDEX(Matches!$J$2:$J$25,I5-1),INDEX(Matches!$A$2:$A$25,I5-1),"")) | B5: =IF(A5="","",IF(J5<=INDEX(Matches!$I$2:$I$25,I5-1),INDEX(Matches!$G$2:$G$25,I5-1),INDEX(Matches!$H$2:$H$25,I5-1))) | C5: =IF(A5="","",COUNTIFS($A$2:A5,A5,$B$2:B5,B5)) | F5: =IF(A5="","",IF(D5="Autogol","",IF(D5="Goal",B5,""))) | G5: =IF(A5="","",IF(D5="","Manca tipo",IF(D5="Goal",IF(E5="","Manca giocatore","OK"),IF(D5="Autogol",IF(E5<>"","Autogol: svuota Player","OK"),"Tipo non valido")))) | H5: =IF(F5="","",VLOOKUP(F5,Validation!$A$2:$B$17,2,FALSE)) | I5: =INT((ROW()-2)/Settings!$B$6)+2 -> 2 | J5: =MOD(ROW()-2,Settings!$B$6)+1 -> 4
A6: =IF(OR(INDEX(Matches!$I$2:$I$25,I6-1)="",INDEX(Matches!$J$2:$J$25,I6-1)=""),"",IF(J6<=INDEX(Matches!$I$2:$I$25,I6-1)+INDEX(Matches!$J$2:$J$25,I6-1),INDEX(Matches!$A$2:$A$25,I6-1),"")) | B6: =IF(A6="","",IF(J6<=INDEX(Matches!$I$2:$I$25,I6-1),INDEX(Matches!$G$2:$G$25,I6-1),INDEX(Matches!$H$2:$H$25,I6-1))) | C6: =IF(A6="","",COUNTIFS($A$2:A6,A6,$B$2:B6,B6)) | F6: =IF(A6="","",IF(D6="Autogol","",IF(D6="Goal",B6,""))) | G6: =IF(A6="","",IF(D6="","Manca tipo",IF(D6="Goal",IF(E6="","Manca giocatore","OK"),IF(D6="Autogol",IF(E6<>"","Autogol: svuota Player","OK"),"Tipo non valido")))) | H6: =IF(F6="","",VLOOKUP(F6,Validation!$A$2:$B$17,2,FALSE)) | I6: =INT((ROW()-2)/Settings!$B$6)+2 -> 2 | J6: =MOD(ROW()-2,Settings!$B$6)+1 -> 5
A7: =IF(OR(INDEX(Matches!$I$2:$I$25,I7-1)="",INDEX(Matches!$J$2:$J$25,I7-1)=""),"",IF(J7<=INDEX(Matches!$I$2:$I$25,I7-1)+INDEX(Matches!$J$2:$J$25,I7-1),INDEX(Matches!$A$2:$A$25,I7-1),"")) | B7: =IF(A7="","",IF(J7<=INDEX(Matches!$I$2:$I$25,I7-1),INDEX(Matches!$G$2:$G$25,I7-1),INDEX(Matches!$H$2:$H$25,I7-1))) | C7: =IF(A7="","",COUNTIFS($A$2:A7,A7,$B$2:B7,B7)) | F7: =IF(A7="","",IF(D7="Autogol","",IF(D7="Goal",B7,""))) | G7: =IF(A7="","",IF(D7="","Manca tipo",IF(D7="Goal",IF(E7="","Manca giocatore","OK"),IF(D7="Autogol",IF(E7<>"","Autogol: svuota Player","OK"),"Tipo non valido")))) | H7: =IF(F7="","",VLOOKUP(F7,Validation!$A$2:$B$17,2,FALSE)) | I7: =INT((ROW()-2)/Settings!$B$6)+2 -> 2 | J7: =MOD(ROW()-2,Settings!$B$6)+1 -> 6
A8: =IF(OR(INDEX(Matches!$I$2:$I$25,I8-1)="",INDEX(Matches!$J$2:$J$25,I8-1)=""),"",IF(J8<=INDEX(Matches!$I$2:$I$25,I8-1)+INDEX(Matches!$J$2:$J$25,I8-1),INDEX(Matches!$A$2:$A$25,I8-1),"")) | B8: =IF(A8="","",IF(J8<=INDEX(Matches!$I$2:$I$25,I8-1),INDEX(Matches!$G$2:$G$25,I8-1),INDEX(Matches!$H$2:$H$25,I8-1))) | C8: =IF(A8="","",COUNTIFS($A$2:A8,A8,$B$2:B8,B8)) | F8: =IF(A8="","",IF(D8="Autogol","",IF(D8="Goal",B8,""))) | G8: =IF(A8="","",IF(D8="","Manca tipo",IF(D8="Goal",IF(E8="","Manca giocatore","OK"),IF(D8="Autogol",IF(E8<>"","Autogol: svuota Player","OK"),"Tipo non valido")))) | H8: =IF(F8="","",VLOOKUP(F8,Validation!$A$2:$B$17,2,FALSE)) | I8: =INT((ROW()-2)/Settings!$B$6)+2 -> 2 | J8: =MOD(ROW()-2,Settings!$B$6)+1 -> 7
A9: =IF(OR(INDEX(Matches!$I$2:$I$25,I9-1)="",INDEX(Matches!$J$2:$J$25,I9-1)=""),"",IF(J9<=INDEX(Matches!$I$2:$I$25,I9-1)+INDEX(Matches!$J$2:$J$25,I9-1),INDEX(Matches!$A$2:$A$25,I9-1),"")) | B9: =IF(A9="","",IF(J9<=INDEX(Matches!$I$2:$I$25,I9-1),INDEX(Matches!$G$2:$G$25,I9-1),INDEX(Matches!$H$2:$H$25,I9-1))) | C9: =IF(A9="","",COUNTIFS($A$2:A9,A9,$B$2:B9,B9)) | F9: =IF(A9="","",IF(D9="Autogol","",IF(D9="Goal",B9,""))) | G9: =IF(A9="","",IF(D9="","Manca tipo",IF(D9="Goal",IF(E9="","Manca giocatore","OK"),IF(D9="Autogol",IF(E9<>"","Autogol: svuota Player","OK"),"Tipo non valido")))) | H9: =IF(F9="","",VLOOKUP(F9,Validation!$A$2:$B$17,2,FALSE)) | I9: =INT((ROW()-2)/Settings!$B$6)+2 -> 2 | J9: =MOD(ROW()-2,Settings!$B$6)+1 -> 8
A10: =IF(OR(INDEX(Matches!$I$2:$I$25,I10-1)="",INDEX(Matches!$J$2:$J$25,I10-1)=""),"",IF(J10<=INDEX(Matches!$I$2:$I$25,I10-1)+INDEX(Matches!$J$2:$J$25,I10-1),INDEX(Matches!$A$2:$A$25,I10-1),"")) | B10: =IF(A10="","",IF(J10<=INDEX(Matches!$I$2:$I$25,I10-1),INDEX(Matches!$G$2:$G$25,I10-1),INDEX(Matches!$H$2:$H$25,I10-1))) | C10: =IF(A10="","",COUNTIFS($A$2:A10,A10,$B$2:B10,B10)) | F10: =IF(A10="","",IF(D10="Autogol","",IF(D10="Goal",B10,""))) | G10: =IF(A10="","",IF(D10="","Manca tipo",IF(D10="Goal",IF(E10="","Manca giocatore","OK"),IF(D10="Autogol",IF(E10<>"","Autogol: svuota Player","OK"),"Tipo non valido")))) | H10: =IF(F10="","",VLOOKUP(F10,Validation!$A$2:$B$17,2,FALSE)) | I10: =INT((ROW()-2)/Settings!$B$6)+2 -> 2 | J10: =MOD(ROW()-2,Settings!$B$6)+1 -> 9
A11: =IF(OR(INDEX(Matches!$I$2:$I$25,I11-1)="",INDEX(Matches!$J$2:$J$25,I11-1)=""),"",IF(J11<=INDEX(Matches!$I$2:$I$25,I11-1)+INDEX(Matches!$J$2:$J$25,I11-1),INDEX(Matches!$A$2:$A$25,I11-1),"")) | B11: =IF(A11="","",IF(J11<=INDEX(Matches!$I$2:$I$25,I11-1),INDEX(Matches!$G$2:$G$25,I11-1),INDEX(Matches!$H$2:$H$25,I11-1))) | C11: =IF(A11="","",COUNTIFS($A$2:A11,A11,$B$2:B11,B11)) | F11: =IF(A11="","",IF(D11="Autogol","",IF(D11="Goal",B11,""))) | G11: =IF(A11="","",IF(D11="","Manca tipo",IF(D11="Goal",IF(E11="","Manca giocatore","OK"),IF(D11="Autogol",IF(E11<>"","Autogol: svuota Player","OK"),"Tipo non valido")))) | H11: =IF(F11="","",VLOOKUP(F11,Validation!$A$2:$B$17,2,FALSE)) | I11: =INT((ROW()-2)/Settings!$B$6)+2 -> 2 | J11: =MOD(ROW()-2,Settings!$B$6)+1 -> 10
A12: =IF(OR(INDEX(Matches!$I$2:$I$25,I12-1)="",INDEX(Matches!$J$2:$J$25,I12-1)=""),"",IF(J12<=INDEX(Matches!$I$2:$I$25,I12-1)+INDEX(Matches!$J$2:$J$25,I12-1),INDEX(Matches!$A$2:$A$25,I12-1),"")) | B12: =IF(A12="","",IF(J12<=INDEX(Matches!$I$2:$I$25,I12-1),INDEX(Matches!$G$2:$G$25,I12-1),INDEX(Matches!$H$2:$H$25,I12-1))) | C12: =IF(A12="","",COUNTIFS($A$2:A12,A12,$B$2:B12,B12)) | F12: =IF(A12="","",IF(D12="Autogol","",IF(D12="Goal",B12,""))) | G12: =IF(A12="","",IF(D12="","Manca tipo",IF(D12="Goal",IF(E12="","Manca giocatore","OK"),IF(D12="Autogol",IF(E12<>"","Autogol: svuota Player","OK"),"Tipo non valido")))) | H12: =IF(F12="","",VLOOKUP(F12,Validation!$A$2:$B$17,2,FALSE)) | I12: =INT((ROW()-2)/Settings!$B$6)+2 -> 2 | J12: =MOD(ROW()-2,Settings!$B$6)+1 -> 11
A13: =IF(OR(INDEX(Matches!$I$2:$I$25,I13-1)="",INDEX(Matches!$J$2:$J$25,I13-1)=""),"",IF(J13<=INDEX(Matches!$I$2:$I$25,I13-1)+INDEX(Matches!$J$2:$J$25,I13-1),INDEX(Matches!$A$2:$A$25,I13-1),"")) | B13: =IF(A13="","",IF(J13<=INDEX(Matches!$I$2:$I$25,I13-1),INDEX(Matches!$G$2:$G$25,I13-1),INDEX(Matches!$H$2:$H$25,I13-1))) | C13: =IF(A13="","",COUNTIFS($A$2:A13,A13,$B$2:B13,B13)) | F13: =IF(A13="","",IF(D13="Autogol","",IF(D13="Goal",B13,""))) | G13: =IF(A13="","",IF(D13="","Manca tipo",IF(D13="Goal",IF(E13="","Manca giocatore","OK"),IF(D13="Autogol",IF(E13<>"","Autogol: svuota Player","OK"),"Tipo non valido")))) | H13: =IF(F13="","",VLOOKUP(F13,Validation!$A$2:$B$17,2,FALSE)) | I13: =INT((ROW()-2)/Settings!$B$6)+2 -> 2 | J13: =MOD(ROW()-2,Settings!$B$6)+1 -> 12
A14: =IF(OR(INDEX(Matches!$I$2:$I$25,I14-1)="",INDEX(Matches!$J$2:$J$25,I14-1)=""),"",IF(J14<=INDEX(Matches!$I$2:$I$25,I14-1)+INDEX(Matches!$J$2:$J$25,I14-1),INDEX(Matches!$A$2:$A$25,I14-1),"")) | B14: =IF(A14="","",IF(J14<=INDEX(Matches!$I$2:$I$25,I14-1),INDEX(Matches!$G$2:$G$25,I14-1),INDEX(Matches!$H$2:$H$25,I14-1))) | C14: =IF(A14="","",COUNTIFS($A$2:A14,A14,$B$2:B14,B14)) | F14: =IF(A14="","",IF(D14="Autogol","",IF(D14="Goal",B14,""))) | G14: =IF(A14="","",IF(D14="","Manca tipo",IF(D14="Goal",IF(E14="","Manca giocatore","OK"),IF(D14="Autogol",IF(E14<>"","Autogol: svuota Player","OK"),"Tipo non valido")))) | H14: =IF(F14="","",VLOOKUP(F14,Validation!$A$2:$B$17,2,FALSE)) | I14: =INT((ROW()-2)/Settings!$B$6)+2 -> 3 | J14: =MOD(ROW()-2,Settings!$B$6)+1 -> 1
... A19: =IF(OR(INDEX(Matches!$I$2:$I$25,I19-1)="",INDEX(Matches!$J$2:$J$25,I19-1)=""),"",IF(J19<=INDEX(Matches!$I$2:$I$25,I19-1)+INDEX(Matches!$J$2:$J$25,I19-1),INDEX(Matches!$A$2:$A$25,I19-1),"")) | B19: =IF(A19="","",IF(J19<=INDEX(Matches!$I$2:$I$25,I19-1),INDEX(Matches!$G$2:$G$25,I19-1),INDEX(Matches!$H$2:$H$25,I19-1))) | C19: =IF(A19="","",COUNTIFS($A$2:A19,A19,$B$2:B19,B19)) | F19: =IF(A19="","",IF(D19="Autogol","",IF(D19="Goal",B19,""))) | G19: =IF(A19="","",IF(D19="","Manca tipo",IF(D19="Goal",IF(E19="","Manca giocatore","OK"),IF(D19="Autogol",IF(E19<>"","Autogol: svuota Player","OK"),"Tipo non valido")))) | H19: =IF(F19="","",VLOOKUP(F19,Validation!$A$2:$B$17,2,FALSE)) | I19: =INT((ROW()-2)/Settings!$B$6)+2 -> 3 | J19: =MOD(ROW()-2,Settings!$B$6)+1 -> 6
A20: =IF(OR(INDEX(Matches!$I$2:$I$25,I20-1)="",INDEX(Matches!$J$2:$J$25,I20-1)=""),"",IF(J20<=INDEX(Matches!$I$2:$I$25,I20-1)+INDEX(Matches!$J$2:$J$25,I20-1),INDEX(Matches!$A$2:$A$25,I20-1),"")) | B20: =IF(A20="","",IF(J20<=INDEX(Matches!$I$2:$I$25,I20-1),INDEX(Matches!$G$2:$G$25,I20-1),INDEX(Matches!$H$2:$H$25,I20-1))) | C20: =IF(A20="","",COUNTIFS($A$2:A20,A20,$B$2:B20,B20)) | D20: =IF(A20="","","Goal") | F20: =IF(A20="","",IF(D20="Autogol","",IF(D20="Goal",B20,""))) | G20: =IF(A20="","",IF(D20="","Manca tipo",IF(D20="Goal",IF(E20="","Manca giocatore","OK"),IF(D20="Autogol",IF(E20<>"","Autogol: svuota Player","OK"),"Tipo non valido")))) | H20: =IF(F20="","",VLOOKUP(F20,Validation!$A$2:$B$17,2,FALSE)) | I20: =INT((ROW()-2)/Settings!$B$6)+2 -> 3 | J20: =MOD(ROW()-2,Settings!$B$6)+1 -> 7
A21: =IF(OR(INDEX(Matches!$I$2:$I$25,I21-1)="",INDEX(Matches!$J$2:$J$25,I21-1)=""),"",IF(J21<=INDEX(Matches!$I$2:$I$25,I21-1)+INDEX(Matches!$J$2:$J$25,I21-1),INDEX(Matches!$A$2:$A$25,I21-1),"")) | B21: =IF(A21="","",IF(J21<=INDEX(Matches!$I$2:$I$25,I21-1),INDEX(Matches!$G$2:$G$25,I21-1),INDEX(Matches!$H$2:$H$25,I21-1))) | C21: =IF(A21="","",COUNTIFS($A$2:A21,A21,$B$2:B21,B21)) | D21: =IF(A21="","","Goal") | F21: =IF(A21="","",IF(D21="Autogol","",IF(D21="Goal",B21,""))) | G21: =IF(A21="","",IF(D21="","Manca tipo",IF(D21="Goal",IF(E21="","Manca giocatore","OK"),IF(D21="Autogol",IF(E21<>"","Autogol: svuota Player","OK"),"Tipo non valido")))) | H21: =IF(F21="","",VLOOKUP(F21,Validation!$A$2:$B$17,2,FALSE)) | I21: =INT((ROW()-2)/Settings!$B$6)+2 -> 3 | J21: =MOD(ROW()-2,Settings!$B$6)+1 -> 8
A22: =IF(OR(INDEX(Matches!$I$2:$I$25,I22-1)="",INDEX(Matches!$J$2:$J$25,I22-1)=""),"",IF(J22<=INDEX(Matches!$I$2:$I$25,I22-1)+INDEX(Matches!$J$2:$J$25,I22-1),INDEX(Matches!$A$2:$A$25,I22-1),"")) | B22: =IF(A22="","",IF(J22<=INDEX(Matches!$I$2:$I$25,I22-1),INDEX(Matches!$G$2:$G$25,I22-1),INDEX(Matches!$H$2:$H$25,I22-1))) | C22: =IF(A22="","",COUNTIFS($A$2:A22,A22,$B$2:B22,B22)) | D22: =IF(A22="","","Goal") | F22: =IF(A22="","",IF(D22="Autogol","",IF(D22="Goal",B22,""))) | G22: =IF(A22="","",IF(D22="","Manca tipo",IF(D22="Goal",IF(E22="","Manca giocatore","OK"),IF(D22="Autogol",IF(E22<>"","Autogol: svuota Player","OK"),"Tipo non valido")))) | H22: =IF(F22="","",VLOOKUP(F22,Validation!$A$2:$B$17,2,FALSE)) | I22: =INT((ROW()-2)/Settings!$B$6)+2 -> 3 | J22: =MOD(ROW()-2,Settings!$B$6)+1 -> 9
A23: =IF(OR(INDEX(Matches!$I$2:$I$25,I23-1)="",INDEX(Matches!$J$2:$J$25,I23-1)=""),"",IF(J23<=INDEX(Matches!$I$2:$I$25,I23-1)+INDEX(Matches!$J$2:$J$25,I23-1),INDEX(Matches!$A$2:$A$25,I23-1),"")) | B23: =IF(A23="","",IF(J23<=INDEX(Matches!$I$2:$I$25,I23-1),INDEX(Matches!$G$2:$G$25,I23-1),INDEX(Matches!$H$2:$H$25,I23-1))) | C23: =IF(A23="","",COUNTIFS($A$2:A23,A23,$B$2:B23,B23)) | D23: =IF(A23="","","Goal") | F23: =IF(A23="","",IF(D23="Autogol","",IF(D23="Goal",B23,""))) | G23: =IF(A23="","",IF(D23="","Manca tipo",IF(D23="Goal",IF(E23="","Manca giocatore","OK"),IF(D23="Autogol",IF(E23<>"","Autogol: svuota Player","OK"),"Tipo non valido")))) | H23: =IF(F23="","",VLOOKUP(F23,Validation!$A$2:$B$17,2,FALSE)) | I23: =INT((ROW()-2)/Settings!$B$6)+2 -> 3 | J23: =MOD(ROW()-2,Settings!$B$6)+1 -> 10
A24: =IF(OR(INDEX(Matches!$I$2:$I$25,I24-1)="",INDEX(Matches!$J$2:$J$25,I24-1)=""),"",IF(J24<=INDEX(Matches!$I$2:$I$25,I24-1)+INDEX(Matches!$J$2:$J$25,I24-1),INDEX(Matches!$A$2:$A$25,I24-1),"")) | B24: =IF(A24="","",IF(J24<=INDEX(Matches!$I$2:$I$25,I24-1),INDEX(Matches!$G$2:$G$25,I24-1),INDEX(Matches!$H$2:$H$25,I24-1))) | C24: =IF(A24="","",COUNTIFS($A$2:A24,A24,$B$2:B24,B24)) | D24: =IF(A24="","","Goal") | F24: =IF(A24="","",IF(D24="Autogol","",IF(D24="Goal",B24,""))) | G24: =IF(A24="","",IF(D24="","Manca tipo",IF(D24="Goal",IF(E24="","Manca giocatore","OK"),IF(D24="Autogol",IF(E24<>"","Autogol: svuota Player","OK"),"Tipo non valido")))) | H24: =IF(F24="","",VLOOKUP(F24,Validation!$A$2:$B$17,2,FALSE)) | I24: =INT((ROW()-2)/Settings!$B$6)+2 -> 3 | J24: =MOD(ROW()-2,Settings!$B$6)+1 -> 11
A25: =IF(OR(INDEX(Matches!$I$2:$I$25,I25-1)="",INDEX(Matches!$J$2:$J$25,I25-1)=""),"",IF(J25<=INDEX(Matches!$I$2:$I$25,I25-1)+INDEX(Matches!$J$2:$J$25,I25-1),INDEX(Matches!$A$2:$A$25,I25-1),"")) | B25: =IF(A25="","",IF(J25<=INDEX(Matches!$I$2:$I$25,I25-1),INDEX(Matches!$G$2:$G$25,I25-1),INDEX(Matches!$H$2:$H$25,I25-1))) | C25: =IF(A25="","",COUNTIFS($A$2:A25,A25,$B$2:B25,B25)) | D25: =IF(A25="","","Goal") | F25: =IF(A25="","",IF(D25="Autogol","",IF(D25="Goal",B25,""))) | G25: =IF(A25="","",IF(D25="","Manca tipo",IF(D25="Goal",IF(E25="","Manca giocatore","OK"),IF(D25="Autogol",IF(E25<>"","Autogol: svuota Player","OK"),"Tipo non valido")))) | H25: =IF(F25="","",VLOOKUP(F25,Validation!$A$2:$B$17,2,FALSE)) | I25: =INT((ROW()-2)/Settings!$B$6)+2 -> 3 | J25: =MOD(ROW()-2,Settings!$B$6)+1 -> 12
A26: =IF(OR(INDEX(Matches!$I$2:$I$25,I26-1)="",INDEX(Matches!$J$2:$J$25,I26-1)=""),"",IF(J26<=INDEX(Matches!$I$2:$I$25,I26-1)+INDEX(Matches!$J$2:$J$25,I26-1),INDEX(Matches!$A$2:$A$25,I26-1),"")) | B26: =IF(A26="","",IF(J26<=INDEX(Matches!$I$2:$I$25,I26-1),INDEX(Matches!$G$2:$G$25,I26-1),INDEX(Matches!$H$2:$H$25,I26-1))) | C26: =IF(A26="","",COUNTIFS($A$2:A26,A26,$B$2:B26,B26)) | F26: =IF(A26="","",IF(D26="Autogol","",IF(D26="Goal",B26,""))) | G26: =IF(A26="","",IF(D26="","Manca tipo",IF(D26="Goal",IF(E26="","Manca giocatore","OK"),IF(D26="Autogol",IF(E26<>"","Autogol: svuota Player","OK"),"Tipo non valido")))) | H26: =IF(F26="","",VLOOKUP(F26,Validation!$A$2:$B$17,2,FALSE)) | I26: =INT((ROW()-2)/Settings!$B$6)+2 -> 4 | J26: =MOD(ROW()-2,Settings!$B$6)+1 -> 1
A27: =IF(OR(INDEX(Matches!$I$2:$I$25,I27-1)="",INDEX(Matches!$J$2:$J$25,I27-1)=""),"",IF(J27<=INDEX(Matches!$I$2:$I$25,I27-1)+INDEX(Matches!$J$2:$J$25,I27-1),INDEX(Matches!$A$2:$A$25,I27-1),"")) | B27: =IF(A27="","",IF(J27<=INDEX(Matches!$I$2:$I$25,I27-1),INDEX(Matches!$G$2:$G$25,I27-1),INDEX(Matches!$H$2:$H$25,I27-1))) | C27: =IF(A27="","",COUNTIFS($A$2:A27,A27,$B$2:B27,B27)) | D27: =IF(A27="","","Goal") | F27: =IF(A27="","",IF(D27="Autogol","",IF(D27="Goal",B27,""))) | G27: =IF(A27="","",IF(D27="","Manca tipo",IF(D27="Goal",IF(E27="","Manca giocatore","OK"),IF(D27="Autogol",IF(E27<>"","Autogol: svuota Player","OK"),"Tipo non valido")))) | H27: =IF(F27="","",VLOOKUP(F27,Validation!$A$2:$B$17,2,FALSE)) | I27: =INT((ROW()-2)/Settings!$B$6)+2 -> 4 | J27: =MOD(ROW()-2,Settings!$B$6)+1 -> 2
A28: =IF(OR(INDEX(Matches!$I$2:$I$25,I28-1)="",INDEX(Matches!$J$2:$J$25,I28-1)=""),"",IF(J28<=INDEX(Matches!$I$2:$I$25,I28-1)+INDEX(Matches!$J$2:$J$25,I28-1),INDEX(Matches!$A$2:$A$25,I28-1),"")) | B28: =IF(A28="","",IF(J28<=INDEX(Matches!$I$2:$I$25,I28-1),INDEX(Matches!$G$2:$G$25,I28-1),INDEX(Matches!$H$2:$H$25,I28-1))) | C28: =IF(A28="","",COUNTIFS($A$2:A28,A28,$B$2:B28,B28)) | D28: =IF(A28="","","Goal") | F28: =IF(A28="","",IF(D28="Autogol","",IF(D28="Goal",B28,""))) | G28: =IF(A28="","",IF(D28="","Manca tipo",IF(D28="Goal",IF(E28="","Manca giocatore","OK"),IF(D28="Autogol",IF(E28<>"","Autogol: svuota Player","OK"),"Tipo non valido")))) | H28: =IF(F28="","",VLOOKUP(F28,Validation!$A$2:$B$17,2,FALSE)) | I28: =INT((ROW()-2)/Settings!$B$6)+2 -> 4 | J28: =MOD(ROW()-2,Settings!$B$6)+1 -> 3
A29: =IF(OR(INDEX(Matches!$I$2:$I$25,I29-1)="",INDEX(Matches!$J$2:$J$25,I29-1)=""),"",IF(J29<=INDEX(Matches!$I$2:$I$25,I29-1)+INDEX(Matches!$J$2:$J$25,I29-1),INDEX(Matches!$A$2:$A$25,I29-1),"")) | B29: =IF(A29="","",IF(J29<=INDEX(Matches!$I$2:$I$25,I29-1),INDEX(Matches!$G$2:$G$25,I29-1),INDEX(Matches!$H$2:$H$25,I29-1))) | C29: =IF(A29="","",COUNTIFS($A$2:A29,A29,$B$2:B29,B29)) | D29: =IF(A29="","","Goal") | F29: =IF(A29="","",IF(D29="Autogol","",IF(D29="Goal",B29,""))) | G29: =IF(A29="","",IF(D29="","Manca tipo",IF(D29="Goal",IF(E29="","Manca giocatore","OK"),IF(D29="Autogol",IF(E29<>"","Autogol: svuota Player","OK"),"Tipo non valido")))) | H29: =IF(F29="","",VLOOKUP(F29,Validation!$A$2:$B$17,2,FALSE)) | I29: =INT((ROW()-2)/Settings!$B$6)+2 -> 4 | J29: =MOD(ROW()-2,Settings!$B$6)+1 -> 4
A30: =IF(OR(INDEX(Matches!$I$2:$I$25,I30-1)="",INDEX(Matches!$J$2:$J$25,I30-1)=""),"",IF(J30<=INDEX(Matches!$I$2:$I$25,I30-1)+INDEX(Matches!$J$2:$J$25,I30-1),INDEX(Matches!$A$2:$A$25,I30-1),"")) | B30: =IF(A30="","",IF(J30<=INDEX(Matches!$I$2:$I$25,I30-1),INDEX(Matches!$G$2:$G$25,I30-1),INDEX(Matches!$H$2:$H$25,I30-1))) | C30: =IF(A30="","",COUNTIFS($A$2:A30,A30,$B$2:B30,B30)) | D30: =IF(A30="","","Goal") | F30: =IF(A30="","",IF(D30="Autogol","",IF(D30="Goal",B30,""))) | G30: =IF(A30="","",IF(D30="","Manca tipo",IF(D30="Goal",IF(E30="","Manca giocatore","OK"),IF(D30="Autogol",IF(E30<>"","Autogol: svuota Player","OK"),"Tipo non valido")))) | H30: =IF(F30="","",VLOOKUP(F30,Validation!$A$2:$B$17,2,FALSE)) | I30: =INT((ROW()-2)/Settings!$B$6)+2 -> 4 | J30: =MOD(ROW()-2,Settings!$B$6)+1 -> 5
A31: =IF(OR(INDEX(Matches!$I$2:$I$25,I31-1)="",INDEX(Matches!$J$2:$J$25,I31-1)=""),"",IF(J31<=INDEX(Matches!$I$2:$I$25,I31-1)+INDEX(Matches!$J$2:$J$25,I31-1),INDEX(Matches!$A$2:$A$25,I31-1),"")) | B31: =IF(A31="","",IF(J31<=INDEX(Matches!$I$2:$I$25,I31-1),INDEX(Matches!$G$2:$G$25,I31-1),INDEX(Matches!$H$2:$H$25,I31-1))) | C31: =IF(A31="","",COUNTIFS($A$2:A31,A31,$B$2:B31,B31)) | D31: =IF(A31="","","Goal") | F31: =IF(A31="","",IF(D31="Autogol","",IF(D31="Goal",B31,""))) | G31: =IF(A31="","",IF(D31="","Manca tipo",IF(D31="Goal",IF(E31="","Manca giocatore","OK"),IF(D31="Autogol",IF(E31<>"","Autogol: svuota Player","OK"),"Tipo non valido")))) | H31: =IF(F31="","",VLOOKUP(F31,Validation!$A$2:$B$17,2,FALSE)) | I31: =INT((ROW()-2)/Settings!$B$6)+2 -> 4 | J31: =MOD(ROW()-2,Settings!$B$6)+1 -> 6
A32: =IF(OR(INDEX(Matches!$I$2:$I$25,I32-1)="",INDEX(Matches!$J$2:$J$25,I32-1)=""),"",IF(J32<=INDEX(Matches!$I$2:$I$25,I32-1)+INDEX(Matches!$J$2:$J$25,I32-1),INDEX(Matches!$A$2:$A$25,I32-1),"")) | B32: =IF(A32="","",IF(J32<=INDEX(Matches!$I$2:$I$25,I32-1),INDEX(Matches!$G$2:$G$25,I32-1),INDEX(Matches!$H$2:$H$25,I32-1))) | C32: =IF(A32="","",COUNTIFS($A$2:A32,A32,$B$2:B32,B32)) | D32: =IF(A32="","","Goal") | F32: =IF(A32="","",IF(D32="Autogol","",IF(D32="Goal",B32,""))) | G32: =IF(A32="","",IF(D32="","Manca tipo",IF(D32="Goal",IF(E32="","Manca giocatore","OK"),IF(D32="Autogol",IF(E32<>"","Autogol: svuota Player","OK"),"Tipo non valido")))) | H32: =IF(F32="","",VLOOKUP(F32,Validation!$A$2:$B$17,2,FALSE)) | I32: =INT((ROW()-2)/Settings!$B$6)+2 -> 4 | J32: =MOD(ROW()-2,Settings!$B$6)+1 -> 7
A33: =IF(OR(INDEX(Matches!$I$2:$I$25,I33-1)="",INDEX(Matches!$J$2:$J$25,I33-1)=""),"",IF(J33<=INDEX(Matches!$I$2:$I$25,I33-1)+INDEX(Matches!$J$2:$J$25,I33-1),INDEX(Matches!$A$2:$A$25,I33-1),"")) | B33: =IF(A33="","",IF(J33<=INDEX(Matches!$I$2:$I$25,I33-1),INDEX(Matches!$G$2:$G$25,I33-1),INDEX(Matches!$H$2:$H$25,I33-1))) | C33: =IF(A33="","",COUNTIFS($A$2:A33,A33,$B$2:B33,B33)) | D33: =IF(A33="","","Goal") | F33: =IF(A33="","",IF(D33="Autogol","",IF(D33="Goal",B33,""))) | G33: =IF(A33="","",IF(D33="","Manca tipo",IF(D33="Goal",IF(E33="","Manca giocatore","OK"),IF(D33="Autogol",IF(E33<>"","Autogol: svuota Player","OK"),"Tipo non valido")))) | H33: =IF(F33="","",VLOOKUP(F33,Validation!$A$2:$B$17,2,FALSE)) | I33: =INT((ROW()-2)/Settings!$B$6)+2 -> 4 | J33: =MOD(ROW()-2,Settings!$B$6)+1 -> 8
A34: =IF(OR(INDEX(Matches!$I$2:$I$25,I34-1)="",INDEX(Matches!$J$2:$J$25,I34-1)=""),"",IF(J34<=INDEX(Matches!$I$2:$I$25,I34-1)+INDEX(Matches!$J$2:$J$25,I34-1),INDEX(Matches!$A$2:$A$25,I34-1),"")) | B34: =IF(A34="","",IF(J34<=INDEX(Matches!$I$2:$I$25,I34-1),INDEX(Matches!$G$2:$G$25,I34-1),INDEX(Matches!$H$2:$H$25,I34-1))) | C34: =IF(A34="","",COUNTIFS($A$2:A34,A34,$B$2:B34,B34)) | D34: =IF(A34="","","Goal") | F34: =IF(A34="","",IF(D34="Autogol","",IF(D34="Goal",B34,""))) | G34: =IF(A34="","",IF(D34="","Manca tipo",IF(D34="Goal",IF(E34="","Manca giocatore","OK"),IF(D34="Autogol",IF(E34<>"","Autogol: svuota Player","OK"),"Tipo non valido")))) | H34: =IF(F34="","",VLOOKUP(F34,Validation!$A$2:$B$17,2,FALSE)) | I34: =INT((ROW()-2)/Settings!$B$6)+2 -> 4 | J34: =MOD(ROW()-2,Settings!$B$6)+1 -> 9
A35: =IF(OR(INDEX(Matches!$I$2:$I$25,I35-1)="",INDEX(Matches!$J$2:$J$25,I35-1)=""),"",IF(J35<=INDEX(Matches!$I$2:$I$25,I35-1)+INDEX(Matches!$J$2:$J$25,I35-1),INDEX(Matches!$A$2:$A$25,I35-1),"")) | B35: =IF(A35="","",IF(J35<=INDEX(Matches!$I$2:$I$25,I35-1),INDEX(Matches!$G$2:$G$25,I35-1),INDEX(Matches!$H$2:$H$25,I35-1))) | C35: =IF(A35="","",COUNTIFS($A$2:A35,A35,$B$2:B35,B35)) | D35: =IF(A35="","","Goal") | F35: =IF(A35="","",IF(D35="Autogol","",IF(D35="Goal",B35,""))) | G35: =IF(A35="","",IF(D35="","Manca tipo",IF(D35="Goal",IF(E35="","Manca giocatore","OK"),IF(D35="Autogol",IF(E35<>"","Autogol: svuota Player","OK"),"Tipo non valido")))) | H35: =IF(F35="","",VLOOKUP(F35,Validation!$A$2:$B$17,2,FALSE)) | I35: =INT((ROW()-2)/Settings!$B$6)+2 -> 4 | J35: =MOD(ROW()-2,Settings!$B$6)+1 -> 10
A36: =IF(OR(INDEX(Matches!$I$2:$I$25,I36-1)="",INDEX(Matches!$J$2:$J$25,I36-1)=""),"",IF(J36<=INDEX(Matches!$I$2:$I$25,I36-1)+INDEX(Matches!$J$2:$J$25,I36-1),INDEX(Matches!$A$2:$A$25,I36-1),"")) | B36: =IF(A36="","",IF(J36<=INDEX(Matches!$I$2:$I$25,I36-1),INDEX(Matches!$G$2:$G$25,I36-1),INDEX(Matches!$H$2:$H$25,I36-1))) | C36: =IF(A36="","",COUNTIFS($A$2:A36,A36,$B$2:B36,B36)) | D36: =IF(A36="","","Goal") | F36: =IF(A36="","",IF(D36="Autogol","",IF(D36="Goal",B36,""))) | G36: =IF(A36="","",IF(D36="","Manca tipo",IF(D36="Goal",IF(E36="","Manca giocatore","OK"),IF(D36="Autogol",IF(E36<>"","Autogol: svuota Player","OK"),"Tipo non valido")))) | H36: =IF(F36="","",VLOOKUP(F36,Validation!$A$2:$B$17,2,FALSE)) | I36: =INT((ROW()-2)/Settings!$B$6)+2 -> 4 | J36: =MOD(ROW()-2,Settings!$B$6)+1 -> 11
A37: =IF(OR(INDEX(Matches!$I$2:$I$25,I37-1)="",INDEX(Matches!$J$2:$J$25,I37-1)=""),"",IF(J37<=INDEX(Matches!$I$2:$I$25,I37-1)+INDEX(Matches!$J$2:$J$25,I37-1),INDEX(Matches!$A$2:$A$25,I37-1),"")) | B37: =IF(A37="","",IF(J37<=INDEX(Matches!$I$2:$I$25,I37-1),INDEX(Matches!$G$2:$G$25,I37-1),INDEX(Matches!$H$2:$H$25,I37-1))) | C37: =IF(A37="","",COUNTIFS($A$2:A37,A37,$B$2:B37,B37)) | D37: =IF(A37="","","Goal") | F37: =IF(A37="","",IF(D37="Autogol","",IF(D37="Goal",B37,""))) | G37: =IF(A37="","",IF(D37="","Manca tipo",IF(D37="Goal",IF(E37="","Manca giocatore","OK"),IF(D37="Autogol",IF(E37<>"","Autogol: svuota Player","OK"),"Tipo non valido")))) | H37: =IF(F37="","",VLOOKUP(F37,Validation!$A$2:$B$17,2,FALSE)) | I37: =INT((ROW()-2)/Settings!$B$6)+2 -> 4 | J37: =MOD(ROW()-2,Settings!$B$6)+1 -> 12
A38: =IF(OR(INDEX(Matches!$I$2:$I$25,I38-1)="",INDEX(Matches!$J$2:$J$25,I38-1)=""),"",IF(J38<=INDEX(Matches!$I$2:$I$25,I38-1)+INDEX(Matches!$J$2:$J$25,I38-1),INDEX(Matches!$A$2:$A$25,I38-1),"")) | B38: =IF(A38="","",IF(J38<=INDEX(Matches!$I$2:$I$25,I38-1),INDEX(Matches!$G$2:$G$25,I38-1),INDEX(Matches!$H$2:$H$25,I38-1))) | C38: =IF(A38="","",COUNTIFS($A$2:A38,A38,$B$2:B38,B38)) | D38: =IF(A38="","","Goal") | F38: =IF(A38="","",IF(D38="Autogol","",IF(D38="Goal",B38,""))) | G38: =IF(A38="","",IF(D38="","Manca tipo",IF(D38="Goal",IF(E38="","Manca giocatore","OK"),IF(D38="Autogol",IF(E38<>"","Autogol: svuota Player","OK"),"Tipo non valido")))) | H38: =IF(F38="","",VLOOKUP(F38,Validation!$A$2:$B$17,2,FALSE)) | I38: =INT((ROW()-2)/Settings!$B$6)+2 -> 5 | J38: =MOD(ROW()-2,Settings!$B$6)+1 -> 1
... A361: =IF(OR(INDEX(Matches!$I$2:$I$25,I361-1)="",INDEX(Matches!$J$2:$J$25,I361-1)=""),"",IF(J361<=INDEX(Matches!$I$2:$I$25,I361-1)+INDEX(Matches!$J$2:$J$25,I361-1),INDEX(Matches!$A$2:$A$25,I361-1),"")) -> #REF! | B361: =IF(A361="","",IF(J361<=INDEX(Matches!$I$2:$I$25,I361-1),INDEX(Matches!$G$2:$G$25,I361-1),INDEX(Matches!$H$2:$H$25,I361-1))) -> #REF! | C361: =IF(A361="","",COUNTIFS($A$2:A361,A361,$B$2:B361,B361)) -> #REF! | D361: =IF(A361="","","Goal") -> #REF! | F361: =IF(A361="","",IF(D361="Autogol","",IF(D361="Goal",B361,""))) -> #REF! | G361: =IF(A361="","",IF(D361="","Manca tipo",IF(D361="Goal",IF(E361="","Manca giocatore","OK"),IF(D361="Autogol",IF(E361<>"","Autogol: svuota Player","OK"),"Tipo non valido")))) -> #REF! | H361: =IF(F361="","",VLOOKUP(F361,Validation!$A$2:$B$17,2,FALSE)) -> #REF! | I361: =INT((ROW()-2)/Settings!$B$6)+2 -> 31 | J361: =MOD(ROW()-2,Settings!$B$6)+1 -> 12

Sheet ScorerData
A1: Player | B1: Team | C1: DisplayName | D1: Goals | E1: SortKey
A2: PIETRO SEGATO | B2: Fatine FC | C2: 1 - PIETRO SEGATO | D2: =COUNTIFS(Goals!$D$2:$D$361,"Goal",Goals!$E$2:$E$361,C2,Goals!$F$2:$F$361,B2) -> 0 | E2: =D2*100000-ROW()/1000 -> -0.002
A3: GIOVANNI BALLO | B3: Fatine FC | C3: 4 - GIOVANNI BALLO | D3: =COUNTIFS(Goals!$D$2:$D$361,"Goal",Goals!$E$2:$E$361,C3,Goals!$F$2:$F$361,B3) -> 0 | E3: =D3*100000-ROW()/1000 -> -0.003
A4: DANIELE MARZOLLA | B4: Fatine FC | C4: 5 - DANIELE MARZOLLA | D4: =COUNTIFS(Goals!$D$2:$D$361,"Goal",Goals!$E$2:$E$361,C4,Goals!$F$2:$F$361,B4) -> 0 | E4: =D4*100000-ROW()/1000 -> -0.004
A5: NICHOLAS MILAN | B5: Fatine FC | C5: 7 - NICHOLAS MILAN | D5: =COUNTIFS(Goals!$D$2:$D$361,"Goal",Goals!$E$2:$E$361,C5,Goals!$F$2:$F$361,B5) -> 0 | E5: =D5*100000-ROW()/1000 -> -0.005
A6: ALESSIO MILAN | B6: Fatine FC | C6: 8 - ALESSIO MILAN | D6: =COUNTIFS(Goals!$D$2:$D$361,"Goal",Goals!$E$2:$E$361,C6,Goals!$F$2:$F$361,B6) -> 0 | E6: =D6*100000-ROW()/1000 -> -0.006
A7: LUCA MARINI | B7: Fatine FC | C7: 10 - LUCA MARINI | D7: =COUNTIFS(Goals!$D$2:$D$361,"Goal",Goals!$E$2:$E$361,C7,Goals!$F$2:$F$361,B7) -> 0 | E7: =D7*100000-ROW()/1000 -> -0.007
A8: DAVIDE GHIRARDI | B8: Fatine FC | C8: 11 - DAVIDE GHIRARDI | D8: =COUNTIFS(Goals!$D$2:$D$361,"Goal",Goals!$E$2:$E$361,C8,Goals!$F$2:$F$361,B8) -> 0 | E8: =D8*100000-ROW()/1000 -> -0.008
A9: NICOLA MARINI | B9: Fatine FC | C9: 23 - NICOLA MARINI (C) | D9: =COUNTIFS(Goals!$D$2:$D$361,"Goal",Goals!$E$2:$E$361,C9,Goals!$F$2:$F$361,B9) -> 0 | E9: =D9*100000-ROW()/1000 -> -0.009
A10: LUCA ROSSETTO | B10: Fatine FC | C10: 69 - LUCA ROSSETTO | D10: =COUNTIFS(Goals!$D$2:$D$361,"Goal",Goals!$E$2:$E$361,C10,Goals!$F$2:$F$361,B10) -> 0 | E10: =D10*100000-ROW()/1000 -> -0.01
A11: MANUEL MEDEA | B11: Fatine FC | C11: 90 - MANUEL MEDEA | D11: =COUNTIFS(Goals!$D$2:$D$361,"Goal",Goals!$E$2:$E$361,C11,Goals!$F$2:$F$361,B11) -> 0 | E11: =D11*100000-ROW()/1000 -> -0.011
A12: BOGDAN ATAMANYUK | B12: FC Internazionale Rovigo | C12: BOGDAN ATAMANYUK | D12: =COUNTIFS(Goals!$D$2:$D$361,"Goal",Goals!$E$2:$E$361,C12,Goals!$F$2:$F$361,B12) -> 0 | E12: =D12*100000-ROW()/1000 -> -0.012
A13: IVAN DENIS SHEVERAK | B13: FC Internazionale Rovigo | C13: IVAN DENIS SHEVERAK | D13: =COUNTIFS(Goals!$D$2:$D$361,"Goal",Goals!$E$2:$E$361,C13,Goals!$F$2:$F$361,B13) -> 0 | E13: =D13*100000-ROW()/1000 -> -0.013
... A158: ALEX BERGO | B158: Piadineria la Salsiccia | C158: 11 - ALEX BERGO | D158: =COUNTIFS(Goals!$D$2:$D$361,"Goal",Goals!$E$2:$E$361,C158,Goals!$F$2:$F$361,B158) -> 0 | E158: =D158*100000-ROW()/1000 -> -0.158

Sheet TopScorers
A1: Pos | B1: Player | C1: Team | D1: Goals
A2: =IFERROR(IF(INDEX(ScorerData!$D$2:$D$158,MATCH(LARGE(ScorerData!$E$2:$E$158,1),ScorerData!$E$2:$E$158,0))>0,1,""),"") -> 1 | B2: =IF($A2="","",INDEX(ScorerData!$A$2:$A$158,MATCH(LARGE(ScorerData!$E$2:$E$158,$A2),ScorerData!$E$2:$E$158,0))) -> STEFANO BRAGHIN | C2: =IF($A2="","",INDEX(ScorerData!$B$2:$B$158,MATCH(LARGE(ScorerData!$E$2:$E$158,$A2),ScorerData!$E$2:$E$158,0))) -> All Blacks | D2: =IF($A2="","",INDEX(ScorerData!$D$2:$D$158,MATCH(LARGE(ScorerData!$E$2:$E$158,$A2),ScorerData!$E$2:$E$158,0))) -> 1
A3: =IFERROR(IF(INDEX(ScorerData!$D$2:$D$158,MATCH(LARGE(ScorerData!$E$2:$E$158,2),ScorerData!$E$2:$E$158,0))>0,2,""),"") | B3: =IF($A3="","",INDEX(ScorerData!$A$2:$A$158,MATCH(LARGE(ScorerData!$E$2:$E$158,$A3),ScorerData!$E$2:$E$158,0))) | C3: =IF($A3="","",INDEX(ScorerData!$B$2:$B$158,MATCH(LARGE(ScorerData!$E$2:$E$158,$A3),ScorerData!$E$2:$E$158,0))) | D3: =IF($A3="","",INDEX(ScorerData!$D$2:$D$158,MATCH(LARGE(ScorerData!$E$2:$E$158,$A3),ScorerData!$E$2:$E$158,0)))
A4: =IFERROR(IF(INDEX(ScorerData!$D$2:$D$158,MATCH(LARGE(ScorerData!$E$2:$E$158,3),ScorerData!$E$2:$E$158,0))>0,3,""),"") | B4: =IF($A4="","",INDEX(ScorerData!$A$2:$A$158,MATCH(LARGE(ScorerData!$E$2:$E$158,$A4),ScorerData!$E$2:$E$158,0))) | C4: =IF($A4="","",INDEX(ScorerData!$B$2:$B$158,MATCH(LARGE(ScorerData!$E$2:$E$158,$A4),ScorerData!$E$2:$E$158,0))) | D4: =IF($A4="","",INDEX(ScorerData!$D$2:$D$158,MATCH(LARGE(ScorerData!$E$2:$E$158,$A4),ScorerData!$E$2:$E$158,0)))
A5: =IFERROR(IF(INDEX(ScorerData!$D$2:$D$158,MATCH(LARGE(ScorerData!$E$2:$E$158,4),ScorerData!$E$2:$E$158,0))>0,4,""),"") | B5: =IF($A5="","",INDEX(ScorerData!$A$2:$A$158,MATCH(LARGE(ScorerData!$E$2:$E$158,$A5),ScorerData!$E$2:$E$158,0))) | C5: =IF($A5="","",INDEX(ScorerData!$B$2:$B$158,MATCH(LARGE(ScorerData!$E$2:$E$158,$A5),ScorerData!$E$2:$E$158,0))) | D5: =IF($A5="","",INDEX(ScorerData!$D$2:$D$158,MATCH(LARGE(ScorerData!$E$2:$E$158,$A5),ScorerData!$E$2:$E$158,0)))
A6: =IFERROR(IF(INDEX(ScorerData!$D$2:$D$158,MATCH(LARGE(ScorerData!$E$2:$E$158,5),ScorerData!$E$2:$E$158,0))>0,5,""),"") | B6: =IF($A6="","",INDEX(ScorerData!$A$2:$A$158,MATCH(LARGE(ScorerData!$E$2:$E$158,$A6),ScorerData!$E$2:$E$158,0))) | C6: =IF($A6="","",INDEX(ScorerData!$B$2:$B$158,MATCH(LARGE(ScorerData!$E$2:$E$158,$A6),ScorerData!$E$2:$E$158,0))) | D6: =IF($A6="","",INDEX(ScorerData!$D$2:$D$158,MATCH(LARGE(ScorerData!$E$2:$E$158,$A6),ScorerData!$E$2:$E$158,0)))
A7: =IFERROR(IF(INDEX(ScorerData!$D$2:$D$158,MATCH(LARGE(ScorerData!$E$2:$E$158,6),ScorerData!$E$2:$E$158,0))>0,6,""),"") | B7: =IF($A7="","",INDEX(ScorerData!$A$2:$A$158,MATCH(LARGE(ScorerData!$E$2:$E$158,$A7),ScorerData!$E$2:$E$158,0))) | C7: =IF($A7="","",INDEX(ScorerData!$B$2:$B$158,MATCH(LARGE(ScorerData!$E$2:$E$158,$A7),ScorerData!$E$2:$E$158,0))) | D7: =IF($A7="","",INDEX(ScorerData!$D$2:$D$158,MATCH(LARGE(ScorerData!$E$2:$E$158,$A7),ScorerData!$E$2:$E$158,0)))
A8: =IFERROR(IF(INDEX(ScorerData!$D$2:$D$158,MATCH(LARGE(ScorerData!$E$2:$E$158,7),ScorerData!$E$2:$E$158,0))>0,7,""),"") | B8: =IF($A8="","",INDEX(ScorerData!$A$2:$A$158,MATCH(LARGE(ScorerData!$E$2:$E$158,$A8),ScorerData!$E$2:$E$158,0))) | C8: =IF($A8="","",INDEX(ScorerData!$B$2:$B$158,MATCH(LARGE(ScorerData!$E$2:$E$158,$A8),ScorerData!$E$2:$E$158,0))) | D8: =IF($A8="","",INDEX(ScorerData!$D$2:$D$158,MATCH(LARGE(ScorerData!$E$2:$E$158,$A8),ScorerData!$E$2:$E$158,0)))
A9: =IFERROR(IF(INDEX(ScorerData!$D$2:$D$158,MATCH(LARGE(ScorerData!$E$2:$E$158,8),ScorerData!$E$2:$E$158,0))>0,8,""),"") | B9: =IF($A9="","",INDEX(ScorerData!$A$2:$A$158,MATCH(LARGE(ScorerData!$E$2:$E$158,$A9),ScorerData!$E$2:$E$158,0))) | C9: =IF($A9="","",INDEX(ScorerData!$B$2:$B$158,MATCH(LARGE(ScorerData!$E$2:$E$158,$A9),ScorerData!$E$2:$E$158,0))) | D9: =IF($A9="","",INDEX(ScorerData!$D$2:$D$158,MATCH(LARGE(ScorerData!$E$2:$E$158,$A9),ScorerData!$E$2:$E$158,0)))
A10: =IFERROR(IF(INDEX(ScorerData!$D$2:$D$158,MATCH(LARGE(ScorerData!$E$2:$E$158,9),ScorerData!$E$2:$E$158,0))>0,9,""),"") | B10: =IF($A10="","",INDEX(ScorerData!$A$2:$A$158,MATCH(LARGE(ScorerData!$E$2:$E$158,$A10),ScorerData!$E$2:$E$158,0))) | C10: =IF($A10="","",INDEX(ScorerData!$B$2:$B$158,MATCH(LARGE(ScorerData!$E$2:$E$158,$A10),ScorerData!$E$2:$E$158,0))) | D10: =IF($A10="","",INDEX(ScorerData!$D$2:$D$158,MATCH(LARGE(ScorerData!$E$2:$E$158,$A10),ScorerData!$E$2:$E$158,0)))
A11: =IFERROR(IF(INDEX(ScorerData!$D$2:$D$158,MATCH(LARGE(ScorerData!$E$2:$E$158,10),ScorerData!$E$2:$E$158,0))>0,10,""),"") | B11: =IF($A11="","",INDEX(ScorerData!$A$2:$A$158,MATCH(LARGE(ScorerData!$E$2:$E$158,$A11),ScorerData!$E$2:$E$158,0))) | C11: =IF($A11="","",INDEX(ScorerData!$B$2:$B$158,MATCH(LARGE(ScorerData!$E$2:$E$158,$A11),ScorerData!$E$2:$E$158,0))) | D11: =IF($A11="","",INDEX(ScorerData!$D$2:$D$158,MATCH(LARGE(ScorerData!$E$2:$E$158,$A11),ScorerData!$E$2:$E$158,0)))
A12: =IFERROR(IF(INDEX(ScorerData!$D$2:$D$158,MATCH(LARGE(ScorerData!$E$2:$E$158,11),ScorerData!$E$2:$E$158,0))>0,11,""),"") | B12: =IF($A12="","",INDEX(ScorerData!$A$2:$A$158,MATCH(LARGE(ScorerData!$E$2:$E$158,$A12),ScorerData!$E$2:$E$158,0))) | C12: =IF($A12="","",INDEX(ScorerData!$B$2:$B$158,MATCH(LARGE(ScorerData!$E$2:$E$158,$A12),ScorerData!$E$2:$E$158,0))) | D12: =IF($A12="","",INDEX(ScorerData!$D$2:$D$158,MATCH(LARGE(ScorerData!$E$2:$E$158,$A12),ScorerData!$E$2:$E$158,0)))
A13: =IFERROR(IF(INDEX(ScorerData!$D$2:$D$158,MATCH(LARGE(ScorerData!$E$2:$E$158,12),ScorerData!$E$2:$E$158,0))>0,12,""),"") | B13: =IF($A13="","",INDEX(ScorerData!$A$2:$A$158,MATCH(LARGE(ScorerData!$E$2:$E$158,$A13),ScorerData!$E$2:$E$158,0))) | C13: =IF($A13="","",INDEX(ScorerData!$B$2:$B$158,MATCH(LARGE(ScorerData!$E$2:$E$158,$A13),ScorerData!$E$2:$E$158,0))) | D13: =IF($A13="","",INDEX(ScorerData!$D$2:$D$158,MATCH(LARGE(ScorerData!$E$2:$E$158,$A13),ScorerData!$E$2:$E$158,0)))
A14: =IFERROR(IF(INDEX(ScorerData!$D$2:$D$158,MATCH(LARGE(ScorerData!$E$2:$E$158,13),ScorerData!$E$2:$E$158,0))>0,13,""),"") | B14: =IF($A14="","",INDEX(ScorerData!$A$2:$A$158,MATCH(LARGE(ScorerData!$E$2:$E$158,$A14),ScorerData!$E$2:$E$158,0))) | C14: =IF($A14="","",INDEX(ScorerData!$B$2:$B$158,MATCH(LARGE(ScorerData!$E$2:$E$158,$A14),ScorerData!$E$2:$E$158,0))) | D14: =IF($A14="","",INDEX(ScorerData!$D$2:$D$158,MATCH(LARGE(ScorerData!$E$2:$E$158,$A14),ScorerData!$E$2:$E$158,0)))
A15: =IFERROR(IF(INDEX(ScorerData!$D$2:$D$158,MATCH(LARGE(ScorerData!$E$2:$E$158,14),ScorerData!$E$2:$E$158,0))>0,14,""),"") | B15: =IF($A15="","",INDEX(ScorerData!$A$2:$A$158,MATCH(LARGE(ScorerData!$E$2:$E$158,$A15),ScorerData!$E$2:$E$158,0))) | C15: =IF($A15="","",INDEX(ScorerData!$B$2:$B$158,MATCH(LARGE(ScorerData!$E$2:$E$158,$A15),ScorerData!$E$2:$E$158,0))) | D15: =IF($A15="","",INDEX(ScorerData!$D$2:$D$158,MATCH(LARGE(ScorerData!$E$2:$E$158,$A15),ScorerData!$E$2:$E$158,0)))
A16: =IFERROR(IF(INDEX(ScorerData!$D$2:$D$158,MATCH(LARGE(ScorerData!$E$2:$E$158,15),ScorerData!$E$2:$E$158,0))>0,15,""),"") | B16: =IF($A16="","",INDEX(ScorerData!$A$2:$A$158,MATCH(LARGE(ScorerData!$E$2:$E$158,$A16),ScorerData!$E$2:$E$158,0))) | C16: =IF($A16="","",INDEX(ScorerData!$B$2:$B$158,MATCH(LARGE(ScorerData!$E$2:$E$158,$A16),ScorerData!$E$2:$E$158,0))) | D16: =IF($A16="","",INDEX(ScorerData!$D$2:$D$158,MATCH(LARGE(ScorerData!$E$2:$E$158,$A16),ScorerData!$E$2:$E$158,0)))
A17: =IFERROR(IF(INDEX(ScorerData!$D$2:$D$158,MATCH(LARGE(ScorerData!$E$2:$E$158,16),ScorerData!$E$2:$E$158,0))>0,16,""),"") | B17: =IF($A17="","",INDEX(ScorerData!$A$2:$A$158,MATCH(LARGE(ScorerData!$E$2:$E$158,$A17),ScorerData!$E$2:$E$158,0))) | C17: =IF($A17="","",INDEX(ScorerData!$B$2:$B$158,MATCH(LARGE(ScorerData!$E$2:$E$158,$A17),ScorerData!$E$2:$E$158,0))) | D17: =IF($A17="","",INDEX(ScorerData!$D$2:$D$158,MATCH(LARGE(ScorerData!$E$2:$E$158,$A17),ScorerData!$E$2:$E$158,0)))
A18: =IFERROR(IF(INDEX(ScorerData!$D$2:$D$158,MATCH(LARGE(ScorerData!$E$2:$E$158,17),ScorerData!$E$2:$E$158,0))>0,17,""),"") | B18: =IF($A18="","",INDEX(ScorerData!$A$2:$A$158,MATCH(LARGE(ScorerData!$E$2:$E$158,$A18),ScorerData!$E$2:$E$158,0))) | C18: =IF($A18="","",INDEX(ScorerData!$B$2:$B$158,MATCH(LARGE(ScorerData!$E$2:$E$158,$A18),ScorerData!$E$2:$E$158,0))) | D18: =IF($A18="","",INDEX(ScorerData!$D$2:$D$158,MATCH(LARGE(ScorerData!$E$2:$E$158,$A18),ScorerData!$E$2:$E$158,0)))
A19: =IFERROR(IF(INDEX(ScorerData!$D$2:$D$158,MATCH(LARGE(ScorerData!$E$2:$E$158,18),ScorerData!$E$2:$E$158,0))>0,18,""),"") | B19: =IF($A19="","",INDEX(ScorerData!$A$2:$A$158,MATCH(LARGE(ScorerData!$E$2:$E$158,$A19),ScorerData!$E$2:$E$158,0))) | C19: =IF($A19="","",INDEX(ScorerData!$B$2:$B$158,MATCH(LARGE(ScorerData!$E$2:$E$158,$A19),ScorerData!$E$2:$E$158,0))) | D19: =IF($A19="","",INDEX(ScorerData!$D$2:$D$158,MATCH(LARGE(ScorerData!$E$2:$E$158,$A19),ScorerData!$E$2:$E$158,0)))
A20: =IFERROR(IF(INDEX(ScorerData!$D$2:$D$158,MATCH(LARGE(ScorerData!$E$2:$E$158,19),ScorerData!$E$2:$E$158,0))>0,19,""),"") | B20: =IF($A20="","",INDEX(ScorerData!$A$2:$A$158,MATCH(LARGE(ScorerData!$E$2:$E$158,$A20),ScorerData!$E$2:$E$158,0))) | C20: =IF($A20="","",INDEX(ScorerData!$B$2:$B$158,MATCH(LARGE(ScorerData!$E$2:$E$158,$A20),ScorerData!$E$2:$E$158,0))) | D20: =IF($A20="","",INDEX(ScorerData!$D$2:$D$158,MATCH(LARGE(ScorerData!$E$2:$E$158,$A20),ScorerData!$E$2:$E$158,0)))
A21: =IFERROR(IF(INDEX(ScorerData!$D$2:$D$158,MATCH(LARGE(ScorerData!$E$2:$E$158,20),ScorerData!$E$2:$E$158,0))>0,20,""),"") | B21: =IF($A21="","",INDEX(ScorerData!$A$2:$A$158,MATCH(LARGE(ScorerData!$E$2:$E$158,$A21),ScorerData!$E$2:$E$158,0))) | C21: =IF($A21="","",INDEX(ScorerData!$B$2:$B$158,MATCH(LARGE(ScorerData!$E$2:$E$158,$A21),ScorerData!$E$2:$E$158,0))) | D21: =IF($A21="","",INDEX(ScorerData!$D$2:$D$158,MATCH(LARGE(ScorerData!$E$2:$E$158,$A21),ScorerData!$E$2:$E$158,0)))
A22: =IFERROR(IF(INDEX(ScorerData!$D$2:$D$158,MATCH(LARGE(ScorerData!$E$2:$E$158,21),ScorerData!$E$2:$E$158,0))>0,21,""),"") | B22: =IF($A22="","",INDEX(ScorerData!$A$2:$A$158,MATCH(LARGE(ScorerData!$E$2:$E$158,$A22),ScorerData!$E$2:$E$158,0))) | C22: =IF($A22="","",INDEX(ScorerData!$B$2:$B$158,MATCH(LARGE(ScorerData!$E$2:$E$158,$A22),ScorerData!$E$2:$E$158,0))) | D22: =IF($A22="","",INDEX(ScorerData!$D$2:$D$158,MATCH(LARGE(ScorerData!$E$2:$E$158,$A22),ScorerData!$E$2:$E$158,0)))
A23: =IFERROR(IF(INDEX(ScorerData!$D$2:$D$158,MATCH(LARGE(ScorerData!$E$2:$E$158,22),ScorerData!$E$2:$E$158,0))>0,22,""),"") | B23: =IF($A23="","",INDEX(ScorerData!$A$2:$A$158,MATCH(LARGE(ScorerData!$E$2:$E$158,$A23),ScorerData!$E$2:$E$158,0))) | C23: =IF($A23="","",INDEX(ScorerData!$B$2:$B$158,MATCH(LARGE(ScorerData!$E$2:$E$158,$A23),ScorerData!$E$2:$E$158,0))) | D23: =IF($A23="","",INDEX(ScorerData!$D$2:$D$158,MATCH(LARGE(ScorerData!$E$2:$E$158,$A23),ScorerData!$E$2:$E$158,0)))
A24: =IFERROR(IF(INDEX(ScorerData!$D$2:$D$158,MATCH(LARGE(ScorerData!$E$2:$E$158,23),ScorerData!$E$2:$E$158,0))>0,23,""),"") | B24: =IF($A24="","",INDEX(ScorerData!$A$2:$A$158,MATCH(LARGE(ScorerData!$E$2:$E$158,$A24),ScorerData!$E$2:$E$158,0))) | C24: =IF($A24="","",INDEX(ScorerData!$B$2:$B$158,MATCH(LARGE(ScorerData!$E$2:$E$158,$A24),ScorerData!$E$2:$E$158,0))) | D24: =IF($A24="","",INDEX(ScorerData!$D$2:$D$158,MATCH(LARGE(ScorerData!$E$2:$E$158,$A24),ScorerData!$E$2:$E$158,0)))
A25: =IFERROR(IF(INDEX(ScorerData!$D$2:$D$158,MATCH(LARGE(ScorerData!$E$2:$E$158,24),ScorerData!$E$2:$E$158,0))>0,24,""),"") | B25: =IF($A25="","",INDEX(ScorerData!$A$2:$A$158,MATCH(LARGE(ScorerData!$E$2:$E$158,$A25),ScorerData!$E$2:$E$158,0))) | C25: =IF($A25="","",INDEX(ScorerData!$B$2:$B$158,MATCH(LARGE(ScorerData!$E$2:$E$158,$A25),ScorerData!$E$2:$E$158,0))) | D25: =IF($A25="","",INDEX(ScorerData!$D$2:$D$158,MATCH(LARGE(ScorerData!$E$2:$E$158,$A25),ScorerData!$E$2:$E$158,0)))
A26: =IFERROR(IF(INDEX(ScorerData!$D$2:$D$158,MATCH(LARGE(ScorerData!$E$2:$E$158,25),ScorerData!$E$2:$E$158,0))>0,25,""),"") | B26: =IF($A26="","",INDEX(ScorerData!$A$2:$A$158,MATCH(LARGE(ScorerData!$E$2:$E$158,$A26),ScorerData!$E$2:$E$158,0))) | C26: =IF($A26="","",INDEX(ScorerData!$B$2:$B$158,MATCH(LARGE(ScorerData!$E$2:$E$158,$A26),ScorerData!$E$2:$E$158,0))) | D26: =IF($A26="","",INDEX(ScorerData!$D$2:$D$158,MATCH(LARGE(ScorerData!$E$2:$E$158,$A26),ScorerData!$E$2:$E$158,0)))
A27: =IFERROR(IF(INDEX(ScorerData!$D$2:$D$158,MATCH(LARGE(ScorerData!$E$2:$E$158,26),ScorerData!$E$2:$E$158,0))>0,26,""),"") | B27: =IF($A27="","",INDEX(ScorerData!$A$2:$A$158,MATCH(LARGE(ScorerData!$E$2:$E$158,$A27),ScorerData!$E$2:$E$158,0))) | C27: =IF($A27="","",INDEX(ScorerData!$B$2:$B$158,MATCH(LARGE(ScorerData!$E$2:$E$158,$A27),ScorerData!$E$2:$E$158,0))) | D27: =IF($A27="","",INDEX(ScorerData!$D$2:$D$158,MATCH(LARGE(ScorerData!$E$2:$E$158,$A27),ScorerData!$E$2:$E$158,0)))
A28: =IFERROR(IF(INDEX(ScorerData!$D$2:$D$158,MATCH(LARGE(ScorerData!$E$2:$E$158,27),ScorerData!$E$2:$E$158,0))>0,27,""),"") | B28: =IF($A28="","",INDEX(ScorerData!$A$2:$A$158,MATCH(LARGE(ScorerData!$E$2:$E$158,$A28),ScorerData!$E$2:$E$158,0))) | C28: =IF($A28="","",INDEX(ScorerData!$B$2:$B$158,MATCH(LARGE(ScorerData!$E$2:$E$158,$A28),ScorerData!$E$2:$E$158,0))) | D28: =IF($A28="","",INDEX(ScorerData!$D$2:$D$158,MATCH(LARGE(ScorerData!$E$2:$E$158,$A28),ScorerData!$E$2:$E$158,0)))
A29: =IFERROR(IF(INDEX(ScorerData!$D$2:$D$158,MATCH(LARGE(ScorerData!$E$2:$E$158,28),ScorerData!$E$2:$E$158,0))>0,28,""),"") | B29: =IF($A29="","",INDEX(ScorerData!$A$2:$A$158,MATCH(LARGE(ScorerData!$E$2:$E$158,$A29),ScorerData!$E$2:$E$158,0))) | C29: =IF($A29="","",INDEX(ScorerData!$B$2:$B$158,MATCH(LARGE(ScorerData!$E$2:$E$158,$A29),ScorerData!$E$2:$E$158,0))) | D29: =IF($A29="","",INDEX(ScorerData!$D$2:$D$158,MATCH(LARGE(ScorerData!$E$2:$E$158,$A29),ScorerData!$E$2:$E$158,0)))
A30: =IFERROR(IF(INDEX(ScorerData!$D$2:$D$158,MATCH(LARGE(ScorerData!$E$2:$E$158,29),ScorerData!$E$2:$E$158,0))>0,29,""),"") | B30: =IF($A30="","",INDEX(ScorerData!$A$2:$A$158,MATCH(LARGE(ScorerData!$E$2:$E$158,$A30),ScorerData!$E$2:$E$158,0))) | C30: =IF($A30="","",INDEX(ScorerData!$B$2:$B$158,MATCH(LARGE(ScorerData!$E$2:$E$158,$A30),ScorerData!$E$2:$E$158,0))) | D30: =IF($A30="","",INDEX(ScorerData!$D$2:$D$158,MATCH(LARGE(ScorerData!$E$2:$E$158,$A30),ScorerData!$E$2:$E$158,0)))
A31: =IFERROR(IF(INDEX(ScorerData!$D$2:$D$158,MATCH(LARGE(ScorerData!$E$2:$E$158,30),ScorerData!$E$2:$E$158,0))>0,30,""),"") | B31: =IF($A31="","",INDEX(ScorerData!$A$2:$A$158,MATCH(LARGE(ScorerData!$E$2:$E$158,$A31),ScorerData!$E$2:$E$158,0))) | C31: =IF($A31="","",INDEX(ScorerData!$B$2:$B$158,MATCH(LARGE(ScorerData!$E$2:$E$158,$A31),ScorerData!$E$2:$E$158,0))) | D31: =IF($A31="","",INDEX(ScorerData!$D$2:$D$158,MATCH(LARGE(ScorerData!$E$2:$E$158,$A31),ScorerData!$E$2:$E$158,0)))
